Workbook
Name NativeTimeline_Leased_Date: #N/A
Name Scenario: #REF!
Name Scenario: 'Pro Forma Model'!#REF!
Name Slicer_Beds: #N/A
Name Slicer_Property_Name: #N/A

Sheet Intro
B7: Click "Enable Editing" to update.
B9: Index
B10: 1 | C10: Weekly Market Updates
B11: 2 | C11: 30-Day Trends
B12: 3 | C12: Data Analysis
B13: 4 | C13: Leasing Trends
B14: 5 | C14: Rent Comps
B15: 6 | C15: Rent Comparison
B16: 7 | C16: Unit-Level Data
B17: 8 | C17: Unit Mix
B18: 9 | C18: Fees & Amenities
B19: 10 | C19: Specials

Sheet Weekly Market Updates
B2: Weekly Market Updates | O2: Week of: | P2: =IFERROR(TEXT(Q2 - 7, "m/d/yyyy") & " - ","") | Q2: 45785
B3: Note: Delta (△) figures show change from previous 7-day period.
B5: Property | C5: Active Concessions | E5: Unit Type | F5: # Leased | G5: △ | H5: Leased Rents | I5: $△ | J5: %△ | K5: # New | L5: △ | M5: New Listing Rents | N5: # Active | O5: △ | P5: Active Listing Rents | Q5: Exposure
B6: =IF(OFFSET('Rent Comparison'!$A$1,1,2)="{{subject.building_name}}","",OFFSET('Rent Comparison'!$A$1,1,2)) | C6: =IF(ISBLANK(B6),"",IFERROR(INDEX(Specials!B:J,MATCH(B6&" - Active",Specials!I:I,0),2),"")) | E6: Studio | F6: =COUNTIFS('Unit-Level Data'!L:L, ">=" & ($Q$2 - 7), 'Unit-Level Data'!L:L, "<" & $Q$2, 'Unit-Level Data'!G:G, 0, 'Unit-Level Data'!B:B, B6) -> 0 | G6: =COUNTIFS('Unit-Level Data'!L:L, ">=" & ($Q$2 - 7), 'Unit-Level Data'!L:L, "<" & $Q$2, 'Unit-Level Data'!G:G, 0, 'Unit-Level Data'!B:B, B6) - COUNTIFS('Unit-Level Data'!L:L, ">=" & ($Q$2 - 14), 'Unit-Level Data'!L:L, "<=" & ($Q$2 - 7), 'Unit-Level Data'!G:G, 0, 'Unit-Level Data'!B:B, B6) -> 0 | H6: =IFERROR(AVERAGEIFS('Unit-Level Data'!O:O,'Unit-Level Data'!L:L, ">=" & ($Q$2 - 7), 'Unit-Level Data'!L:L, "<" & $Q$2, 'Unit-Level Data'!G:G, 0, 'Unit-Level Data'!B:B, B6),"") | I6: =IFERROR( AVERAGEIFS('Unit-Level Data'!O:O, 'Unit-Level Data'!L:L, ">=" & ($Q$2 - 7), 'Unit-Level Data'!L:L, "<" & $Q$2, 'Unit-Level Data'!G:G, 0, 'Unit-Level Data'!B:B, B6) - AVERAGEIFS('Unit-Level Data'!O:O, 'Unit-Level Data'!L:L, ">=" & ($Q$2 - 14), 'Unit-Level Data'!L:L, "<=" & ($Q$2 - 7), 'Unit-Level Data'!G:G, 0, 'Unit-Level Data'!B:B, B6), 0) -> 0 | J6: =IFERROR(I6/AVERAGEIFS('Unit-Level Data'!O:O, 'Unit-Level Data'!L:L, ">=" & ($Q$2 - 14), 'Unit-Level Data'!L:L, "<=" & ($Q$2 - 7), 'Unit-Level Data'!G:G, 0, 'Unit-Level Data'!B:B, B6),0) -> 0 | K6: =COUNTIFS('Unit-Level Data'!K:K, ">=" & ($Q$2 - 7), 'Unit-Level Data'!K:K, "<" & $Q$2, 'Unit-Level Data'!G:G, 0, 'Unit-Level Data'!B:B, B6) -> 0 | L6: =COUNTIFS( 'Unit-Level Data'!K:K, ">=" & ($Q$2 - 7), 'Unit-Level Data'!K:K, "<" & $Q$2, 'Unit-Level Data'!G:G, 0, 'Unit-Level Data'!B:B, B6 ) - COUNTIFS( 'Unit-Level Data'!K:K, ">=" & ($Q$2 - 14), 'Unit-Level Data'!K:K, "<=" & ($Q$2 - 7), 'Unit-Level Data'!G:G, 0, 'Unit-Level Data'!B:B, B6 ) -> 0 | M6: =IFERROR(AVERAGEIFS('Unit-Level Data'!O:O,'Unit-Level Data'!K:K,">="&($Q$2-7), 'Unit-Level Data'!K:K,"<="&$Q$2, 'Unit-Level Data'!G:G,0, 'Unit-Level Data'!B:B,B6),"") | N6: =COUNTIFS('Unit-Level Data'!B:B, B6, 'Unit-Level Data'!G:G, 0, 'Unit-Level Data'!L:L, "") -> 0 | O6: =N6-(N6-K6+F6) -> 0 | P6: =IFERROR(AVERAGEIFS('Unit-Level Data'!O:O,'Unit-Level Data'!B:B, B6, 'Unit-Level Data'!G:G, 0, 'Unit-Level Data'!L:L, ""),"") | Q6: =IFERROR(N6/SUMIFS('Unit Mix'!G:G,'Unit Mix'!D:D,0,'Unit Mix'!B:B,B6),"")
B7: =IF(OFFSET('Rent Comps'!$A$1,3,2)="{{subject.full_address}}","",OFFSET('Rent Comps'!$A$1,3,2)) | E7: 1 BR | F7: =COUNTIFS('Unit-Level Data'!L:L, ">=" & ($Q$2 - 7), 'Unit-Level Data'!L:L, "<" & $Q$2, 'Unit-Level Data'!G:G, 1, 'Unit-Level Data'!B:B, B6) -> 0 | G7: =COUNTIFS('Unit-Level Data'!L:L, ">=" & ($Q$2 - 7), 'Unit-Level Data'!L:L, "<" & $Q$2, 'Unit-Level Data'!G:G, 1, 'Unit-Level Data'!B:B, B6) - COUNTIFS('Unit-Level Data'!L:L, ">=" & ($Q$2 - 14), 'Unit-Level Data'!L:L, "<=" & ($Q$2 - 7), 'Unit-Level Data'!G:G, 1, 'Unit-Level Data'!B:B, B6) -> 0 | H7: =IFERROR(AVERAGEIFS('Unit-Level Data'!O:O,'Unit-Level Data'!L:L, ">=" & ($Q$2 - 7), 'Unit-Level Data'!L:L, "<" & $Q$2, 'Unit-Level Data'!G:G, 1, 'Unit-Level Data'!B:B, B6),"") | I7: =IFERROR( AVERAGEIFS('Unit-Level Data'!O:O, 'Unit-Level Data'!L:L, ">=" & ($Q$2 - 7), 'Unit-Level Data'!L:L, "<" & $Q$2, 'Unit-Level Data'!G:G, 1, 'Unit-Level Data'!B:B, B6) - AVERAGEIFS('Unit-Level Data'!O:O, 'Unit-Level Data'!L:L, ">=" & ($Q$2 - 14), 'Unit-Level Data'!L:L, "<=" & ($Q$2 - 7), 'Unit-Level Data'!G:G, 1, 'Unit-Level Data'!B:B, B6), 0) -> 0 | J7: =IFERROR(I7/AVERAGEIFS('Unit-Level Data'!O:O, 'Unit-Level Data'!L:L, ">=" & ($Q$2 - 14), 'Unit-Level Data'!L:L, "<=" & ($Q$2 - 7), 'Unit-Level Data'!G:G, 1, 'Unit-Level Data'!B:B, B6),0) -> 0 | K7: =COUNTIFS('Unit-Level Data'!K:K, ">=" & ($Q$2 - 7), 'Unit-Level Data'!K:K, "<" & $Q$2, 'Unit-Level Data'!G:G, 1, 'Unit-Level Data'!B:B, B6) -> 0 | L7: =COUNTIFS( 'Unit-Level Data'!K:K, ">=" & ($Q$2 - 7), 'Unit-Level Data'!K:K, "<" & $Q$2, 'Unit-Level Data'!G:G, 1, 'Unit-Level Data'!B:B, B6 ) - COUNTIFS( 'Unit-Level Data'!K:K, ">=" & ($Q$2 - 14), 'Unit-Level Data'!K:K, "<=" & ($Q$2 - 7), 'Unit-Level Data'!G:G, 1, 'Unit-Level Data'!B:B, B6 ) -> 0 | M7: =IFERROR(AVERAGEIFS('Unit-Level Data'!O:O,'Unit-Level Data'!K:K,">="&($Q$2-7), 'Unit-Level Data'!K:K,"<="&$Q$2, 'Unit-Level Data'!G:G,1, 'Unit-Level Data'!B:B,B6),"") | N7: =COUNTIFS('Unit-Level Data'!B:B, B6, 'Unit-Level Data'!G:G, 1, 'Unit-Level Data'!L:L, "") -> 0 | O7: =N7-(N7-K7+F7) -> 0 | P7: =IFERROR(AVERAGEIFS('Unit-Level Data'!O:O,'Unit-Level Data'!B:B, B6, 'Unit-Level Data'!G:G, 1, 'Unit-Level Data'!L:L, ""),"") | Q7: =IFERROR(N7/SUMIFS('Unit Mix'!G:G,'Unit Mix'!D:D,1,'Unit Mix'!B:B,B6),"")
B8: =IF(OFFSET('Rent Comparison'!$A$1,2,2)="{{subject.management_company}}","",OFFSET('Rent Comparison'!$A$1,2,2)) | E8: 2 BR | F8: =COUNTIFS('Unit-Level Data'!L:L, ">=" & ($Q$2 - 7), 'Unit-Level Data'!L:L, "<" & $Q$2, 'Unit-Level Data'!G:G, 2, 'Unit-Level Data'!B:B, B6) -> 0 | G8: =COUNTIFS('Unit-Level Data'!L:L, ">=" & ($Q$2 - 7), 'Unit-Level Data'!L:L, "<" & $Q$2, 'Unit-Level Data'!G:G, 2, 'Unit-Level Data'!B:B, B6) - COUNTIFS('Unit-Level Data'!L:L, ">=" & ($Q$2 - 14), 'Unit-Level Data'!L:L, "<=" & ($Q$2 - 7), 'Unit-Level Data'!G:G, 2, 'Unit-Level Data'!B:B, B6) -> 0 | H8: =IFERROR(AVERAGEIFS('Unit-Level Data'!O:O,'Unit-Level Data'!L:L, ">=" & ($Q$2 - 7), 'Unit-Level Data'!L:L, "<" & $Q$2, 'Unit-Level Data'!G:G, 2, 'Unit-Level Data'!B:B, B6),"") | I8: =IFERROR( AVERAGEIFS('Unit-Level Data'!O:O, 'Unit-Level Data'!L:L, ">=" & ($Q$2 - 7), 'Unit-Level Data'!L:L, "<" & $Q$2, 'Unit-Level Data'!G:G, 2, 'Unit-Level Data'!B:B, B6) - AVERAGEIFS('Unit-Level Data'!O:O, 'Unit-Level Data'!L:L, ">=" & ($Q$2 - 14), 'Unit-Level Data'!L:L, "<=" & ($Q$2 - 7), 'Unit-Level Data'!G:G, 2, 'Unit-Level Data'!B:B, B6), 0) -> 0 | J8: =IFERROR(I8/AVERAGEIFS('Unit-Level Data'!O:O, 'Unit-Level Data'!L:L, ">=" & ($Q$2 - 14), 'Unit-Level Data'!L:L, "<=" & ($Q$2 - 7), 'Unit-Level Data'!G:G, 2, 'Unit-Level Data'!B:B, B6),0) -> 0 | K8: =COUNTIFS('Unit-Level Data'!K:K, ">=" & ($Q$2 - 7), 'Unit-Level Data'!K:K, "<" & $Q$2, 'Unit-Level Data'!G:G, 2, 'Unit-Level Data'!B:B, B6) -> 0 | L8: =COUNTIFS( 'Unit-Level Data'!K:K, ">=" & ($Q$2 - 7), 'Unit-Level Data'!K:K, "<" & $Q$2, 'Unit-Level Data'!G:G, 2, 'Unit-Level Data'!B:B, B6 ) - COUNTIFS( 'Unit-Level Data'!K:K, ">=" & ($Q$2 - 14), 'Unit-Level Data'!K:K, "<=" & ($Q$2 - 7), 'Unit-Level Data'!G:G, 2, 'Unit-Level Data'!B:B, B6 ) -> 0 | M8: =IFERROR(AVERAGEIFS('Unit-Level Data'!O:O,'Unit-Level Data'!K:K,">="&($Q$2-7), 'Unit-Level Data'!K:K,"<="&$Q$2, 'Unit-Level Data'!G:G,2, 'Unit-Level Data'!B:B,B6),"") | N8: =COUNTIFS('Unit-Level Data'!B:B, B6, 'Unit-Level Data'!G:G, 2, 'Unit-Level Data'!L:L, "") -> 0 | O8: =N8-(N8-K8+F8) -> 0 | P8: =IFERROR(AVERAGEIFS('Unit-Level Data'!O:O,'Unit-Level Data'!B:B, B6, 'Unit-Level Data'!G:G, 2, 'Unit-Level Data'!L:L, ""),"") | Q8: =IFERROR(N8/SUMIFS('Unit Mix'!G:G,'Unit Mix'!D:D,2,'Unit Mix'!B:B,B6),"")
B9: =IF(OFFSET('Rent Comparison'!$A$1,3,2)="{{subject.property_website}}","",OFFSET('Rent Comparison'!$A$1,3,2)) | E9: 3 BR | F9: =COUNTIFS('Unit-Level Data'!L:L, ">=" & ($Q$2 - 7), 'Unit-Level Data'!L:L, "<" & $Q$2, 'Unit-Level Data'!G:G, 3, 'Unit-Level Data'!B:B, B6) -> 0 | G9: =COUNTIFS('Unit-Level Data'!L:L, ">=" & ($Q$2 - 7), 'Unit-Level Data'!L:L, "<" & $Q$2, 'Unit-Level Data'!G:G, 3, 'Unit-Level Data'!B:B, B6) - COUNTIFS('Unit-Level Data'!L:L, ">=" & ($Q$2 - 14), 'Unit-Level Data'!L:L, "<=" & ($Q$2 - 7), 'Unit-Level Data'!G:G, 3, 'Unit-Level Data'!B:B, B6) -> 0 | H9: =IFERROR(AVERAGEIFS('Unit-Level Data'!O:O,'Unit-Level Data'!L:L, ">=" & ($Q$2 - 7), 'Unit-Level Data'!L:L, "<" & $Q$2, 'Unit-Level Data'!G:G, 3, 'Unit-Level Data'!B:B, B6),"") | I9: =IFERROR( AVERAGEIFS('Unit-Level Data'!O:O, 'Unit-Level Data'!L:L, ">=" & ($Q$2 - 7), 'Unit-Level Data'!L:L, "<" & $Q$2, 'Unit-Level Data'!G:G, 3, 'Unit-Level Data'!B:B, B6) - AVERAGEIFS('Unit-Level Data'!O:O, 'Unit-Level Data'!L:L, ">=" & ($Q$2 - 14), 'Unit-Level Data'!L:L, "<=" & ($Q$2 - 7), 'Unit-Level Data'!G:G, 3, 'Unit-Level Data'!B:B, B6), 0) -> 0 | J9: =IFERROR(I9/AVERAGEIFS('Unit-Level Data'!O:O, 'Unit-Level Data'!L:L, ">=" & ($Q$2 - 14), 'Unit-Level Data'!L:L, "<=" & ($Q$2 - 7), 'Unit-Level Data'!G:G, 3, 'Unit-Level Data'!B:B, B6),0) -> 0 | K9: =COUNTIFS('Unit-Level Data'!K:K, ">=" & ($Q$2 - 7), 'Unit-Level Data'!K:K, "<" & $Q$2, 'Unit-Level Data'!G:G, 3, 'Unit-Level Data'!B:B, B6) -> 0 | L9: =COUNTIFS( 'Unit-Level Data'!K:K, ">=" & ($Q$2 - 7), 'Unit-Level Data'!K:K, "<" & $Q$2, 'Unit-Level Data'!G:G, 3, 'Unit-Level Data'!B:B, B6 ) - COUNTIFS( 'Unit-Level Data'!K:K, ">=" & ($Q$2 - 14), 'Unit-Level Data'!K:K, "<=" & ($Q$2 - 7), 'Unit-Level Data'!G:G, 3, 'Unit-Level Data'!B:B, B6 ) -> 0 | M9: =IFERROR(AVERAGEIFS('Unit-Level Data'!O:O,'Unit-Level Data'!K:K,">="&($Q$2-7), 'Unit-Level Data'!K:K,"<="&$Q$2, 'Unit-Level Data'!G:G,3, 'Unit-Level Data'!B:B,B6),"") | N9: =COUNTIFS('Unit-Level Data'!B:B, B6, 'Unit-Level Data'!G:G, 3, 'Unit-Level Data'!L:L, "") -> 0 | O9: =N9-(N9-K9+F9) -> 0 | P9: =IFERROR(AVERAGEIFS('Unit-Level Data'!O:O,'Unit-Level Data'!B:B, B6, 'Unit-Level Data'!G:G, 3, 'Unit-Level Data'!L:L, ""),"") | Q9: =IFERROR(N9/SUMIFS('Unit Mix'!G:G,'Unit Mix'!D:D,3,'Unit Mix'!B:B,B6),"")
B10: =IF(OFFSET('Rent Comparison'!$A$1,1,6)="{{h:comparables.#.building_name}}","",OFFSET('Rent Comparison'!$A$1,1,6)) | C10: =IF(ISBLANK(B10),"",IFERROR(INDEX(Specials!B:J,MATCH(B10&" - Active",Specials!I:I,0),2),"")) | E10: Studio | F10: =COUNTIFS('Unit-Level Data'!L:L, ">=" & ($Q$2 - 7), 'Unit-Level Data'!L:L, "<" & $Q$2, 'Unit-Level Data'!G:G, 0, 'Unit-Level Data'!B:B, B10) -> 0 | G10: =COUNTIFS('Unit-Level Data'!L:L, ">=" & ($Q$2 - 7), 'Unit-Level Data'!L:L, "<" & $Q$2, 'Unit-Level Data'!G:G, 0, 'Unit-Level Data'!B:B, B10) - COUNTIFS('Unit-Level Data'!L:L, ">=" & ($Q$2 - 14), 'Unit-Level Data'!L:L, "<=" & ($Q$2 - 7), 'Unit-Level Data'!G:G, 0, 'Unit-Level Data'!B:B, B10) -> 0 | H10: =IFERROR(AVERAGEIFS('Unit-Level Data'!O:O,'Unit-Level Data'!L:L, ">=" & ($Q$2 - 7), 'Unit-Level Data'!L:L, "<" & $Q$2, 'Unit-Level Data'!G:G, 0, 'Unit-Level Data'!B:B, B10),"") | I10: =IFERROR( AVERAGEIFS('Unit-Level Data'!O:O, 'Unit-Level Data'!L:L, ">=" & ($Q$2 - 7), 'Unit-Level Data'!L:L, "<" & $Q$2, 'Unit-Level Data'!G:G, 0, 'Unit-Level Data'!B:B, B10) - AVERAGEIFS('Unit-Level Data'!O:O, 'Unit-Level Data'!L:L, ">=" & ($Q$2 - 14), 'Unit-Level Data'!L:L, "<=" & ($Q$2 - 7), 'Unit-Level Data'!G:G, 0, 'Unit-Level Data'!B:B, B10), 0) -> 0 | J10: =IFERROR(I10/AVERAGEIFS('Unit-Level Data'!O:O, 'Unit-Level Data'!L:L, ">=" & ($Q$2 - 14), 'Unit-Level Data'!L:L, "<=" & ($Q$2 - 7), 'Unit-Level Data'!G:G, 0, 'Unit-Level Data'!B:B, B10),0) -> 0 | K10: =COUNTIFS('Unit-Level Data'!K:K, ">=" & ($Q$2 - 7), 'Unit-Level Data'!K:K, "<" & $Q$2, 'Unit-Level Data'!G:G, 0, 'Unit-Level Data'!B:B, B10) -> 0 | L10: =COUNTIFS( 'Unit-Level Data'!K:K, ">=" & ($Q$2 - 7), 'Unit-Level Data'!K:K, "<" & $Q$2, 'Unit-Level Data'!G:G, 0, 'Unit-Level Data'!B:B, B10 ) - COUNTIFS( 'Unit-Level Data'!K:K, ">=" & ($Q$2 - 14), 'Unit-Level Data'!K:K, "<=" & ($Q$2 - 7), 'Unit-Level Data'!G:G, 0, 'Unit-Level Data'!B:B, B10 ) -> 0 | M10: =IFERROR(AVERAGEIFS('Unit-Level Data'!O:O,'Unit-Level Data'!K:K,">="&($Q$2-7), 'Unit-Level Data'!K:K,"<="&$Q$2, 'Unit-Level Data'!G:G,0, 'Unit-Level Data'!B:B,B10),"") | N10: =COUNTIFS('Unit-Level Data'!B:B, B10, 'Unit-Level Data'!G:G, 0, 'Unit-Level Data'!L:L, "") -> 0 | O10: =N10-(N10-K10+F10) -> 0 | P10: =IFERROR(AVERAGEIFS('Unit-Level Data'!O:O,'Unit-Level Data'!B:B, B10, 'Unit-Level Data'!G:G, 0, 'Unit-Level Data'!L:L, ""),"") | Q10: =IFERROR(N10/SUMIFS('Unit Mix'!G:G,'Unit Mix'!D:D,0,'Unit Mix'!B:B,B10),"")
B11: =IF(OFFSET('Rent Comps'!$A$1,4,2)="{{v:comparables.#.full_address}}","",OFFSET('Rent Comps'!$A$1,4,2)) | E11: 1 BR | F11: =COUNTIFS('Unit-Level Data'!L:L, ">=" & ($Q$2 - 7), 'Unit-Level Data'!L:L, "<" & $Q$2, 'Unit-Level Data'!G:G, 1, 'Unit-Level Data'!B:B, B10) -> 0 | G11: =COUNTIFS('Unit-Level Data'!L:L, ">=" & ($Q$2 - 7), 'Unit-Level Data'!L:L, "<" & $Q$2, 'Unit-Level Data'!G:G, 1, 'Unit-Level Data'!B:B, B10) - COUNTIFS('Unit-Level Data'!L:L, ">=" & ($Q$2 - 14), 'Unit-Level Data'!L:L, "<=" & ($Q$2 - 7), 'Unit-Level Data'!G:G, 1, 'Unit-Level Data'!B:B, B10) -> 0 | H11: =IFERROR(AVERAGEIFS('Unit-Level Data'!O:O,'Unit-Level Data'!L:L, ">=" & ($Q$2 - 7), 'Unit-Level Data'!L:L, "<" & $Q$2, 'Unit-Level Data'!G:G, 1, 'Unit-Level Data'!B:B, B10),"") | I11: =IFERROR( AVERAGEIFS('Unit-Level Data'!O:O, 'Unit-Level Data'!L:L, ">=" & ($Q$2 - 7), 'Unit-Level Data'!L:L, "<" & $Q$2, 'Unit-Level Data'!G:G, 1, 'Unit-Level Data'!B:B, B10) - AVERAGEIFS('Unit-Level Data'!O:O, 'Unit-Level Data'!L:L, ">=" & ($Q$2 - 14), 'Unit-Level Data'!L:L, "<=" & ($Q$2 - 7), 'Unit-Level Data'!G:G, 1, 'Unit-Level Data'!B:B, B10), 0) -> 0 | J11: =IFERROR(I11/AVERAGEIFS('Unit-Level Data'!O:O, 'Unit-Level Data'!L:L, ">=" & ($Q$2 - 14), 'Unit-Level Data'!L:L, "<=" & ($Q$2 - 7), 'Unit-Level Data'!G:G, 1, 'Unit-Level Data'!B:B, B10),0) -> 0 | K11: =COUNTIFS('Unit-Level Data'!K:K, ">=" & ($Q$2 - 7), 'Unit-Level Data'!K:K, "<" & $Q$2, 'Unit-Level Data'!G:G, 1, 'Unit-Level Data'!B:B, B10) -> 0 | L11: =COUNTIFS( 'Unit-Level Data'!K:K, ">=" & ($Q$2 - 7), 'Unit-Level Data'!K:K, "<" & $Q$2, 'Unit-Level Data'!G:G, 1, 'Unit-Level Data'!B:B, B10 ) - COUNTIFS( 'Unit-Level Data'!K:K, ">=" & ($Q$2 - 14), 'Unit-Level Data'!K:K, "<=" & ($Q$2 - 7), 'Unit-Level Data'!G:G, 1, 'Unit-Level Data'!B:B, B10 ) -> 0 | M11: =IFERROR(AVERAGEIFS('Unit-Level Data'!O:O,'Unit-Level Data'!K:K,">="&($Q$2-7), 'Unit-Level Data'!K:K,"<="&$Q$2, 'Unit-Level Data'!G:G,1, 'Unit-Level Data'!B:B,B10),"") | N11: =COUNTIFS('Unit-Level Data'!B:B, B10, 'Unit-Level Data'!G:G, 1, 'Unit-Level Data'!L:L, "") -> 0 | O11: =N11-(N11-K11+F11) -> 0 | P11: =IFERROR(AVERAGEIFS('Unit-Level Data'!O:O,'Unit-Level Data'!B:B, B10, 'Unit-Level Data'!G:G, 1, 'Unit-Level Data'!L:L, ""),"") | Q11: =IFERROR(N11/SUMIFS('Unit Mix'!G:G,'Unit Mix'!D:D,1,'Unit Mix'!B:B,B10),"")
B12: =IF(OFFSET('Rent Comparison'!$A$1,2,6)="{{h:comparables.#.management_company}}","",OFFSET('Rent Comparison'!$A$1,2,6)) | E12: 2 BR | F12: =COUNTIFS('Unit-Level Data'!L:L, ">=" & ($Q$2 - 7), 'Unit-Level Data'!L:L, "<" & $Q$2, 'Unit-Level Data'!G:G, 2, 'Unit-Level Data'!B:B, B10) -> 0 | G12: =COUNTIFS('Unit-Level Data'!L:L, ">=" & ($Q$2 - 7), 'Unit-Level Data'!L:L, "<" & $Q$2, 'Unit-Level Data'!G:G, 2, 'Unit-Level Data'!B:B, B10) - COUNTIFS('Unit-Level Data'!L:L, ">=" & ($Q$2 - 14), 'Unit-Level Data'!L:L, "<=" & ($Q$2 - 7), 'Unit-Level Data'!G:G, 2, 'Unit-Level Data'!B:B, B10) -> 0 | H12: =IFERROR(AVERAGEIFS('Unit-Level Data'!O:O,'Unit-Level Data'!L:L, ">=" & ($Q$2 - 7), 'Unit-Level Data'!L:L, "<" & $Q$2, 'Unit-Level Data'!G:G, 2, 'Unit-Level Data'!B:B, B10),"") | I12: =IFERROR( AVERAGEIFS('Unit-Level Data'!O:O, 'Unit-Level Data'!L:L, ">=" & ($Q$2 - 7), 'Unit-Level Data'!L:L, "<" & $Q$2, 'Unit-Level Data'!G:G, 2, 'Unit-Level Data'!B:B, B10) - AVERAGEIFS('Unit-Level Data'!O:O, 'Unit-Level Data'!L:L, ">=" & ($Q$2 - 14), 'Unit-Level Data'!L:L, "<=" & ($Q$2 - 7), 'Unit-Level Data'!G:G, 2, 'Unit-Level Data'!B:B, B10), 0) -> 0 | J12: =IFERROR(I12/AVERAGEIFS('Unit-Level Data'!O:O, 'Unit-Level Data'!L:L, ">=" & ($Q$2 - 14), 'Unit-Level Data'!L:L, "<=" & ($Q$2 - 7), 'Unit-Level Data'!G:G, 2, 'Unit-Level Data'!B:B, B10),0) -> 0 | K12: =COUNTIFS('Unit-Level Data'!K:K, ">=" & ($Q$2 - 7), 'Unit-Level Data'!K:K, "<" & $Q$2, 'Unit-Level Data'!G:G, 2, 'Unit-Level Data'!B:B, B10) -> 0 | L12: =COUNTIFS( 'Unit-Level Data'!K:K, ">=" & ($Q$2 - 7), 'Unit-Level Data'!K:K, "<" & $Q$2, 'Unit-Level Data'!G:G, 2, 'Unit-Level Data'!B:B, B10 ) - COUNTIFS( 'Unit-Level Data'!K:K, ">=" & ($Q$2 - 14), 'Unit-Level Data'!K:K, "<=" & ($Q$2 - 7), 'Unit-Level Data'!G:G, 2, 'Unit-Level Data'!B:B, B10 ) -> 0 | M12: =IFERROR(AVERAGEIFS('Unit-Level Data'!O:O,'Unit-Level Data'!K:K,">="&($Q$2-7), 'Unit-Level Data'!K:K,"<="&$Q$2, 'Unit-Level Data'!G:G,2, 'Unit-Level Data'!B:B,B10),"") | N12: =COUNTIFS('Unit-Level Data'!B:B, B10, 'Unit-Level Data'!G:G, 2, 'Unit-Level Data'!L:L, "") -> 0 | O12: =N12-(N12-K12+F12) -> 0 | P12: =IFERROR(AVERAGEIFS('Unit-Level Data'!O:O,'Unit-Level Data'!B:B, B10, 'Unit-Level Data'!G:G, 2, 'Unit-Level Data'!L:L, ""),"") | Q12: =IFERROR(N12/SUMIFS('Unit Mix'!G:G,'Unit Mix'!D:D,2,'Unit Mix'!B:B,B10),"")
B13: =IF(OFFSET('Rent Comparison'!$A$1,3,6)="{{h:comparables.#.property_website}}","",OFFSET('Rent Comparison'!$A$1,3,6)) | E13: 3 BR | F13: =COUNTIFS('Unit-Level Data'!L:L, ">=" & ($Q$2 - 7), 'Unit-Level Data'!L:L, "<" & $Q$2, 'Unit-Level Data'!G:G, 3, 'Unit-Level Data'!B:B, B10) -> 0 | G13: =COUNTIFS('Unit-Level Data'!L:L, ">=" & ($Q$2 - 7), 'Unit-Level Data'!L:L, "<" & $Q$2, 'Unit-Level Data'!G:G, 3, 'Unit-Level Data'!B:B, B10) - COUNTIFS('Unit-Level Data'!L:L, ">=" & ($Q$2 - 14), 'Unit-Level Data'!L:L, "<=" & ($Q$2 - 7), 'Unit-Level Data'!G:G, 3, 'Unit-Level Data'!B:B, B10) -> 0 | H13: =IFERROR(AVERAGEIFS('Unit-Level Data'!O:O,'Unit-Level Data'!L:L, ">=" & ($Q$2 - 7), 'Unit-Level Data'!L:L, "<" & $Q$2, 'Unit-Level Data'!G:G, 3, 'Unit-Level Data'!B:B, B10),"") | I13: =IFERROR( AVERAGEIFS('Unit-Level Data'!O:O, 'Unit-Level Data'!L:L, ">=" & ($Q$2 - 7), 'Unit-Level Data'!L:L, "<" & $Q$2, 'Unit-Level Data'!G:G, 3, 'Unit-Level Data'!B:B, B10) - AVERAGEIFS('Unit-Level Data'!O:O, 'Unit-Level Data'!L:L, ">=" & ($Q$2 - 14), 'Unit-Level Data'!L:L, "<=" & ($Q$2 - 7), 'Unit-Level Data'!G:G, 3, 'Unit-Level Data'!B:B, B10), 0) -> 0 | J13: =IFERROR(I13/AVERAGEIFS('Unit-Level Data'!O:O, 'Unit-Level Data'!L:L, ">=" & ($Q$2 - 14), 'Unit-Level Data'!L:L, "<=" & ($Q$2 - 7), 'Unit-Level Data'!G:G, 3, 'Unit-Level Data'!B:B, B10),0) -> 0 | K13: =COUNTIFS('Unit-Level Data'!K:K, ">=" & ($Q$2 - 7), 'Unit-Level Data'!K:K, "<" & $Q$2, 'Unit-Level Data'!G:G, 3, 'Unit-Level Data'!B:B, B10) -> 0 | L13: =COUNTIFS( 'Unit-Level Data'!K:K, ">=" & ($Q$2 - 7), 'Unit-Level Data'!K:K, "<" & $Q$2, 'Unit-Level Data'!G:G, 3, 'Unit-Level Data'!B:B, B10 ) - COUNTIFS( 'Unit-Level Data'!K:K, ">=" & ($Q$2 - 14), 'Unit-Level Data'!K:K, "<=" & ($Q$2 - 7), 'Unit-Level Data'!G:G, 3, 'Unit-Level Data'!B:B, B10 ) -> 0 | M13: =IFERROR(AVERAGEIFS('Unit-Level Data'!O:O,'Unit-Level Data'!K:K,">="&($Q$2-7), 'Unit-Level Data'!K:K,"<="&$Q$2, 'Unit-Level Data'!G:G,3, 'Unit-Level Data'!B:B,B10),"") | N13: =COUNTIFS('Unit-Level Data'!B:B, B10, 'Unit-Level Data'!G:G, 3, 'Unit-Level Data'!L:L, "") -> 0 | O13: =N13-(N13-K13+F13) -> 0 | P13: =IFERROR(AVERAGEIFS('Unit-Level Data'!O:O,'Unit-Level Data'!B:B, B10, 'Unit-Level Data'!G:G, 3, 'Unit-Level Data'!L:L, ""),"") | Q13: =IFERROR(N13/SUMIFS('Unit Mix'!G:G,'Unit Mix'!D:D,3,'Unit Mix'!B:B,B10),"")
B14: =IF(ISBLANK(OFFSET('Rent Comparison'!$A$1,1,7)),"",OFFSET('Rent Comparison'!$A$1,1,7)) | C14: =IF(ISBLANK(B14),"",IFERROR(INDEX(Specials!B:J,MATCH(B14&" - Active",Specials!I:I,0),2),"")) | E14: Studio | F14: =COUNTIFS('Unit-Level Data'!L:L, ">=" & ($Q$2 - 7), 'Unit-Level Data'!L:L, "<" & $Q$2, 'Unit-Level Data'!G:G, 0, 'Unit-Level Data'!B:B, B14) -> 0 | G14: =COUNTIFS('Unit-Level Data'!L:L, ">=" & ($Q$2 - 7), 'Unit-Level Data'!L:L, "<" & $Q$2, 'Unit-Level Data'!G:G, 0, 'Unit-Level Data'!B:B, B14) - COUNTIFS('Unit-Level Data'!L:L, ">=" & ($Q$2 - 14), 'Unit-Level Data'!L:L, "<=" & ($Q$2 - 7), 'Unit-Level Data'!G:G, 0, 'Unit-Level Data'!B:B, B14) -> 0 | H14: =IFERROR(AVERAGEIFS('Unit-Level Data'!O:O,'Unit-Level Data'!L:L, ">=" & ($Q$2 - 7), 'Unit-Level Data'!L:L, "<" & $Q$2, 'Unit-Level Data'!G:G, 0, 'Unit-Level Data'!B:B, B14),"") | I14: =IFERROR( AVERAGEIFS('Unit-Level Data'!O:O, 'Unit-Level Data'!L:L, ">=" & ($Q$2 - 7), 'Unit-Level Data'!L:L, "<" & $Q$2, 'Unit-Level Data'!G:G, 0, 'Unit-Level Data'!B:B, B14) - AVERAGEIFS('Unit-Level Data'!O:O, 'Unit-Level Data'!L:L, ">=" & ($Q$2 - 14), 'Unit-Level Data'!L:L, "<=" & ($Q$2 - 7), 'Unit-Level Data'!G:G, 0, 'Unit-Level Data'!B:B, B14), 0) -> 0 | J14: =IFERROR(I14/AVERAGEIFS('Unit-Level Data'!O:O, 'Unit-Level Data'!L:L, ">=" & ($Q$2 - 14), 'Unit-Level Data'!L:L, "<=" & ($Q$2 - 7), 'Unit-Level Data'!G:G, 0, 'Unit-Level Data'!B:B, B14),0) -> 0 | K14: =COUNTIFS('Unit-Level Data'!K:K, ">=" & ($Q$2 - 7), 'Unit-Level Data'!K:K, "<" & $Q$2, 'Unit-Level Data'!G:G, 0, 'Unit-Level Data'!B:B, B14) -> 0 | L14: =COUNTIFS( 'Unit-Level Data'!K:K, ">=" & ($Q$2 - 7), 'Unit-Level Data'!K:K, "<" & $Q$2, 'Unit-Level Data'!G:G, 0, 'Unit-Level Data'!B:B, B14 ) - COUNTIFS( 'Unit-Level Data'!K:K, ">=" & ($Q$2 - 14), 'Unit-Level Data'!K:K, "<=" & ($Q$2 - 7), 'Unit-Level Data'!G:G, 0, 'Unit-Level Data'!B:B, B14 ) -> 0 | M14: =IFERROR(AVERAGEIFS('Unit-Level Data'!O:O,'Unit-Level Data'!K:K,">="&($Q$2-7), 'Unit-Level Data'!K:K,"<="&$Q$2, 'Unit-Level Data'!G:G,0, 'Unit-Level Data'!B:B,B14),"") | N14: =COUNTIFS('Unit-Level Data'!B:B, B14, 'Unit-Level Data'!G:G, 0, 'Unit-Level Data'!L:L, "") -> 0 | O14: =N14-(N14-K14+F14) -> 0 | P14: =IFERROR(AVERAGEIFS('Unit-Level Data'!O:O,'Unit-Level Data'!B:B, B14, 'Unit-Level Data'!G:G, 0, 'Unit-Level Data'!L:L, ""),"") | Q14: =IFERROR(N14/SUMIFS('Unit Mix'!G:G,'Unit Mix'!D:D,0,'Unit Mix'!B:B,B14),"")
B15: =IF(ISBLANK(OFFSET('Rent Comps'!$A$1,5,2)),"",OFFSET('Rent Comps'!$A$1,5,2)) | E15: 1 BR | F15: =COUNTIFS('Unit-Level Data'!L:L, ">=" & ($Q$2 - 7), 'Unit-Level Data'!L:L, "<" & $Q$2, 'Unit-Level Data'!G:G, 1, 'Unit-Level Data'!B:B, B14) -> 0 | G15: =COUNTIFS('Unit-Level Data'!L:L, ">=" & ($Q$2 - 7), 'Unit-Level Data'!L:L, "<" & $Q$2, 'Unit-Level Data'!G:G, 1, 'Unit-Level Data'!B:B, B14) - COUNTIFS('Unit-Level Data'!L:L, ">=" & ($Q$2 - 14), 'Unit-Level Data'!L:L, "<=" & ($Q$2 - 7), 'Unit-Level Data'!G:G, 1, 'Unit-Level Data'!B:B, B14) -> 0 | H15: =IFERROR(AVERAGEIFS('Unit-Level Data'!O:O,'Unit-Level Data'!L:L, ">=" & ($Q$2 - 7), 'Unit-Level Data'!L:L, "<" & $Q$2, 'Unit-Level Data'!G:G, 1, 'Unit-Level Data'!B:B, B14),"") | I15: =IFERROR( AVERAGEIFS('Unit-Level Data'!O:O, 'Unit-Level Data'!L:L, ">=" & ($Q$2 - 7), 'Unit-Level Data'!L:L, "<" & $Q$2, 'Unit-Level Data'!G:G, 1, 'Unit-Level Data'!B:B, B14) - AVERAGEIFS('Unit-Level Data'!O:O, 'Unit-Level Data'!L:L, ">=" & ($Q$2 - 14), 'Unit-Level Data'!L:L, "<=" & ($Q$2 - 7), 'Unit-Level Data'!G:G, 1, 'Unit-Level Data'!B:B, B14), 0) -> 0 | J15: =IFERROR(I15/AVERAGEIFS('Unit-Level Data'!O:O, 'Unit-Level Data'!L:L, ">=" & ($Q$2 - 14), 'Unit-Level Data'!L:L, "<=" & ($Q$2 - 7), 'Unit-Level Data'!G:G, 1, 'Unit-Level Data'!B:B, B14),0) -> 0 | K15: =COUNTIFS('Unit-Level Data'!K:K, ">=" & ($Q$2 - 7), 'Unit-Level Data'!K:K, "<" & $Q$2, 'Unit-Level Data'!G:G, 1, 'Unit-Level Data'!B:B, B14) -> 0 | L15: =COUNTIFS( 'Unit-Level Data'!K:K, ">=" & ($Q$2 - 7), 'Unit-Level Data'!K:K, "<" & $Q$2, 'Unit-Level Data'!G:G, 1, 'Unit-Level Data'!B:B, B14 ) - COUNTIFS( 'Unit-Level Data'!K:K, ">=" & ($Q$2 - 14), 'Unit-Level Data'!K:K, "<=" & ($Q$2 - 7), 'Unit-Level Data'!G:G, 1, 'Unit-Level Data'!B:B, B14 ) -> 0 | M15: =IFERROR(AVERAGEIFS('Unit-Level Data'!O:O,'Unit-Level Data'!K:K,">="&($Q$2-7), 'Unit-Level Data'!K:K,"<="&$Q$2, 'Unit-Level Data'!G:G,1, 'Unit-Level Data'!B:B,B14),"") | N15: =COUNTIFS('Unit-Level Data'!B:B, B14, 'Unit-Level Data'!G:G, 1, 'Unit-Level Data'!L:L, "") -> 0 | O15: =N15-(N15-K15+F15) -> 0 | P15: =IFERROR(AVERAGEIFS('Unit-Level Data'!O:O,'Unit-Level Data'!B:B, B14, 'Unit-Level Data'!G:G, 1, 'Unit-Level Data'!L:L, ""),"") | Q15: =IFERROR(N15/SUMIFS('Unit Mix'!G:G,'Unit Mix'!D:D,1,'Unit Mix'!B:B,B14),"")
B16: =IF(ISBLANK(OFFSET('Rent Comparison'!$A$1,2,7)),"",OFFSET('Rent Comparison'!$A$1,2,7)) | E16: 2 BR | F16: =COUNTIFS('Unit-Level Data'!L:L, ">=" & ($Q$2 - 7), 'Unit-Level Data'!L:L, "<" & $Q$2, 'Unit-Level Data'!G:G, 2, 'Unit-Level Data'!B:B, B14) -> 0 | G16: =COUNTIFS('Unit-Level Data'!L:L, ">=" & ($Q$2 - 7), 'Unit-Level Data'!L:L, "<" & $Q$2, 'Unit-Level Data'!G:G, 2, 'Unit-Level Data'!B:B, B14) - COUNTIFS('Unit-Level Data'!L:L, ">=" & ($Q$2 - 14), 'Unit-Level Data'!L:L, "<=" & ($Q$2 - 7), 'Unit-Level Data'!G:G, 2, 'Unit-Level Data'!B:B, B14) -> 0 | H16: =IFERROR(AVERAGEIFS('Unit-Level Data'!O:O,'Unit-Level Data'!L:L, ">=" & ($Q$2 - 7), 'Unit-Level Data'!L:L, "<" & $Q$2, 'Unit-Level Data'!G:G, 2, 'Unit-Level Data'!B:B, B14),"") | I16: =IFERROR( AVERAGEIFS('Unit-Level Data'!O:O, 'Unit-Level Data'!L:L, ">=" & ($Q$2 - 7), 'Unit-Level Data'!L:L, "<" & $Q$2, 'Unit-Level Data'!G:G, 2, 'Unit-Level Data'!B:B, B14) - AVERAGEIFS('Unit-Level Data'!O:O, 'Unit-Level Data'!L:L, ">=" & ($Q$2 - 14), 'Unit-Level Data'!L:L, "<=" & ($Q$2 - 7), 'Unit-Level Data'!G:G, 2, 'Unit-Level Data'!B:B, B14), 0) -> 0 | J16: =IFERROR(I16/AVERAGEIFS('Unit-Level Data'!O:O, 'Unit-Level Data'!L:L, ">=" & ($Q$2 - 14), 'Unit-Level Data'!L:L, "<=" & ($Q$2 - 7), 'Unit-Level Data'!G:G, 2, 'Unit-Level Data'!B:B, B14),0) -> 0 | K16: =COUNTIFS('Unit-Level Data'!K:K, ">=" & ($Q$2 - 7), 'Unit-Level Data'!K:K, "<" & $Q$2, 'Unit-Level Data'!G:G, 2, 'Unit-Level Data'!B:B, B14) -> 0 | L16: =COUNTIFS( 'Unit-Level Data'!K:K, ">=" & ($Q$2 - 7), 'Unit-Level Data'!K:K, "<" & $Q$2, 'Unit-Level Data'!G:G, 2, 'Unit-Level Data'!B:B, B14 ) - COUNTIFS( 'Unit-Level Data'!K:K, ">=" & ($Q$2 - 14), 'Unit-Level Data'!K:K, "<=" & ($Q$2 - 7), 'Unit-Level Data'!G:G, 2, 'Unit-Level Data'!B:B, B14 ) -> 0 | M16: =IFERROR(AVERAGEIFS('Unit-Level Data'!O:O,'Unit-Level Data'!K:K,">="&($Q$2-7), 'Unit-Level Data'!K:K,"<="&$Q$2, 'Unit-Level Data'!G:G,2, 'Unit-Level Data'!B:B,B14),"") | N16: =COUNTIFS('Unit-Level Data'!B:B, B14, 'Unit-Level Data'!G:G, 2, 'Unit-Level Data'!L:L, "") -> 0 | O16: =N16-(N16-K16+F16) -> 0 | P16: =IFERROR(AVERAGEIFS('Unit-Level Data'!O:O,'Unit-Level Data'!B:B, B14, 'Unit-Level Data'!G:G, 2, 'Unit-Level Data'!L:L, ""),"") | Q16: =IFERROR(N16/SUMIFS('Unit Mix'!G:G,'Unit Mix'!D:D,2,'Unit Mix'!B:B,B14),"")
B17: =IF(ISBLANK(OFFSET('Rent Comparison'!$A$1,3,7)),"",OFFSET('Rent Comparison'!$A$1,3,7)) | E17: 3 BR | F17: =COUNTIFS('Unit-Level Data'!L:L, ">=" & ($Q$2 - 7), 'Unit-Level Data'!L:L, "<" & $Q$2, 'Unit-Level Data'!G:G, 3, 'Unit-Level Data'!B:B, B14) -> 0 | G17: =COUNTIFS('Unit-Level Data'!L:L, ">=" & ($Q$2 - 7), 'Unit-Level Data'!L:L, "<" & $Q$2, 'Unit-Level Data'!G:G, 3, 'Unit-Level Data'!B:B, B14) - COUNTIFS('Unit-Level Data'!L:L, ">=" & ($Q$2 - 14), 'Unit-Level Data'!L:L, "<=" & ($Q$2 - 7), 'Unit-Level Data'!G:G, 3, 'Unit-Level Data'!B:B, B14) -> 0 | H17: =IFERROR(AVERAGEIFS('Unit-Level Data'!O:O,'Unit-Level Data'!L:L, ">=" & ($Q$2 - 7), 'Unit-Level Data'!L:L, "<" & $Q$2, 'Unit-Level Data'!G:G, 3, 'Unit-Level Data'!B:B, B14),"") | I17: =IFERROR( AVERAGEIFS('Unit-Level Data'!O:O, 'Unit-Level Data'!L:L, ">=" & ($Q$2 - 7), 'Unit-Level Data'!L:L, "<" & $Q$2, 'Unit-Level Data'!G:G, 3, 'Unit-Level Data'!B:B, B14) - AVERAGEIFS('Unit-Level Data'!O:O, 'Unit-Level Data'!L:L, ">=" & ($Q$2 - 14), 'Unit-Level Data'!L:L, "<=" & ($Q$2 - 7), 'Unit-Level Data'!G:G, 3, 'Unit-Level Data'!B:B, B14), 0) -> 0 | J17: =IFERROR(I17/AVERAGEIFS('Unit-Level Data'!O:O, 'Unit-Level Data'!L:L, ">=" & ($Q$2 - 14), 'Unit-Level Data'!L:L, "<=" & ($Q$2 - 7), 'Unit-Level Data'!G:G, 3, 'Unit-Level Data'!B:B, B14),0) -> 0 | K17: =COUNTIFS('Unit-Level Data'!K:K, ">=" & ($Q$2 - 7), 'Unit-Level Data'!K:K, "<" & $Q$2, 'Unit-Level Data'!G:G, 3, 'Unit-Level Data'!B:B, B14) -> 0 | L17: =COUNTIFS( 'Unit-Level Data'!K:K, ">=" & ($Q$2 - 7), 'Unit-Level Data'!K:K, "<" & $Q$2, 'Unit-Level Data'!G:G, 3, 'Unit-Level Data'!B:B, B14 ) - COUNTIFS( 'Unit-Level Data'!K:K, ">=" & ($Q$2 - 14), 'Unit-Level Data'!K:K, "<=" & ($Q$2 - 7), 'Unit-Level Data'!G:G, 3, 'Unit-Level Data'!B:B, B14 ) -> 0 | M17: =IFERROR(AVERAGEIFS('Unit-Level Data'!O:O,'Unit-Level Data'!K:K,">="&($Q$2-7), 'Unit-Level Data'!K:K,"<="&$Q$2, 'Unit-Level Data'!G:G,3, 'Unit-Level Data'!B:B,B14),"") | N17: =COUNTIFS('Unit-Level Data'!B:B, B14, 'Unit-Level Data'!G:G, 3, 'Unit-Level Data'!L:L, "") -> 0 | O17: =N17-(N17-K17+F17) -> 0 | P17: =IFERROR(AVERAGEIFS('Unit-Level Data'!O:O,'Unit-Level Data'!B:B, B14, 'Unit-Level Data'!G:G, 3, 'Unit-Level Data'!L:L, ""),"") | Q17: =IFERROR(N17/SUMIFS('Unit Mix'!G:G,'Unit Mix'!D:D,3,'Unit Mix'!B:B,B14),"")
B18: =IF(ISBLANK(OFFSET('Rent Comparison'!$A$1,1,8)),"",OFFSET('Rent Comparison'!$A$1,1,8)) | C18: =IF(ISBLANK(B18),"",IFERROR(INDEX(Specials!B:J,MATCH(B18&" - Active",Specials!I:I,0),2),"")) | E18: Studio | F18: =COUNTIFS('Unit-Level Data'!L:L, ">=" & ($Q$2 - 7), 'Unit-Level Data'!L:L, "<" & $Q$2, 'Unit-Level Data'!G:G, 0, 'Unit-Level Data'!B:B, B18) -> 0 | G18: =COUNTIFS('Unit-Level Data'!L:L, ">=" & ($Q$2 - 7), 'Unit-Level Data'!L:L, "<" & $Q$2, 'Unit-Level Data'!G:G, 0, 'Unit-Level Data'!B:B, B18) - COUNTIFS('Unit-Level Data'!L:L, ">=" & ($Q$2 - 14), 'Unit-Level Data'!L:L, "<=" & ($Q$2 - 7), 'Unit-Level Data'!G:G, 0, 'Unit-Level Data'!B:B, B18) -> 0 | H18: =IFERROR(AVERAGEIFS('Unit-Level Data'!O:O,'Unit-Level Data'!L:L, ">=" & ($Q$2 - 7), 'Unit-Level Data'!L:L, "<" & $Q$2, 'Unit-Level Data'!G:G, 0, 'Unit-Level Data'!B:B, B18),"") | I18: =IFERROR( AVERAGEIFS('Unit-Level Data'!O:O, 'Unit-Level Data'!L:L, ">=" & ($Q$2 - 7), 'Unit-Level Data'!L:L, "<" & $Q$2, 'Unit-Level Data'!G:G, 0, 'Unit-Level Data'!B:B, B18) - AVERAGEIFS('Unit-Level Data'!O:O, 'Unit-Level Data'!L:L, ">=" & ($Q$2 - 14), 'Unit-Level Data'!L:L, "<=" & ($Q$2 - 7), 'Unit-Level Data'!G:G, 0, 'Unit-Level Data'!B:B, B18), 0) -> 0 | J18: =IFERROR(I18/AVERAGEIFS('Unit-Level Data'!O:O, 'Unit-Level Data'!L:L, ">=" & ($Q$2 - 14), 'Unit-Level Data'!L:L, "<=" & ($Q$2 - 7), 'Unit-Level Data'!G:G, 0, 'Unit-Level Data'!B:B, B18),0) -> 0 | K18: =COUNTIFS('Unit-Level Data'!K:K, ">=" & ($Q$2 - 7), 'Unit-Level Data'!K:K, "<" & $Q$2, 'Unit-Level Data'!G:G, 0, 'Unit-Level Data'!B:B, B18) -> 0 | L18: =COUNTIFS( 'Unit-Level Data'!K:K, ">=" & ($Q$2 - 7), 'Unit-Level Data'!K:K, "<" & $Q$2, 'Unit-Level Data'!G:G, 0, 'Unit-Level Data'!B:B, B18 ) - COUNTIFS( 'Unit-Level Data'!K:K, ">=" & ($Q$2 - 14), 'Unit-Level Data'!K:K, "<=" & ($Q$2 - 7), 'Unit-Level Data'!G:G, 0, 'Unit-Level Data'!B:B, B18 ) -> 0 | M18: =IFERROR(AVERAGEIFS('Unit-Level Data'!O:O,'Unit-Level Data'!K:K,">="&($Q$2-7), 'Unit-Level Data'!K:K,"<="&$Q$2, 'Unit-Level Data'!G:G,0, 'Unit-Level Data'!B:B,B18),"") | N18: =COUNTIFS('Unit-Level Data'!B:B, B18, 'Unit-Level Data'!G:G, 0, 'Unit-Level Data'!L:L, "") -> 0 | O18: =N18-(N18-K18+F18) -> 0 | P18: =IFERROR(AVERAGEIFS('Unit-Level Data'!O:O,'Unit-Level Data'!B:B, B18, 'Unit-Level Data'!G:G, 0, 'Unit-Level Data'!L:L, ""),"") | Q18: =IFERROR(N18/SUMIFS('Unit Mix'!G:G,'Unit Mix'!D:D,0,'Unit Mix'!B:B,B18),"")
B19: =IF(ISBLANK(OFFSET('Rent Comps'!$A$1,6,2)),"",OFFSET('Rent Comps'!$A$1,6,2)) | E19: 1 BR | F19: =COUNTIFS('Unit-Level Data'!L:L, ">=" & ($Q$2 - 7), 'Unit-Level Data'!L:L, "<" & $Q$2, 'Unit-Level Data'!G:G, 1, 'Unit-Level Data'!B:B, B18) -> 0 | G19: =COUNTIFS('Unit-Level Data'!L:L, ">=" & ($Q$2 - 7), 'Unit-Level Data'!L:L, "<" & $Q$2, 'Unit-Level Data'!G:G, 1, 'Unit-Level Data'!B:B, B18) - COUNTIFS('Unit-Level Data'!L:L, ">=" & ($Q$2 - 14), 'Unit-Level Data'!L:L, "<=" & ($Q$2 - 7), 'Unit-Level Data'!G:G, 1, 'Unit-Level Data'!B:B, B18) -> 0 | H19: =IFERROR(AVERAGEIFS('Unit-Level Data'!O:O,'Unit-Level Data'!L:L, ">=" & ($Q$2 - 7), 'Unit-Level Data'!L:L, "<" & $Q$2, 'Unit-Level Data'!G:G, 1, 'Unit-Level Data'!B:B, B18),"") | I19: =IFERROR( AVERAGEIFS('Unit-Level Data'!O:O, 'Unit-Level Data'!L:L, ">=" & ($Q$2 - 7), 'Unit-Level Data'!L:L, "<" & $Q$2, 'Unit-Level Data'!G:G, 1, 'Unit-Level Data'!B:B, B18) - AVERAGEIFS('Unit-Level Data'!O:O, 'Unit-Level Data'!L:L, ">=" & ($Q$2 - 14), 'Unit-Level Data'!L:L, "<=" & ($Q$2 - 7), 'Unit-Level Data'!G:G, 1, 'Unit-Level Data'!B:B, B18), 0) -> 0 | J19: =IFERROR(I19/AVERAGEIFS('Unit-Level Data'!O:O, 'Unit-Level Data'!L:L, ">=" & ($Q$2 - 14), 'Unit-Level Data'!L:L, "<=" & ($Q$2 - 7), 'Unit-Level Data'!G:G, 1, 'Unit-Level Data'!B:B, B18),0) -> 0 | K19: =COUNTIFS('Unit-Level Data'!K:K, ">=" & ($Q$2 - 7), 'Unit-Level Data'!K:K, "<" & $Q$2, 'Unit-Level Data'!G:G, 1, 'Unit-Level Data'!B:B, B18) -> 0 | L19: =COUNTIFS( 'Unit-Level Data'!K:K, ">=" & ($Q$2 - 7), 'Unit-Level Data'!K:K, "<" & $Q$2, 'Unit-Level Data'!G:G, 1, 'Unit-Level Data'!B:B, B18 ) - COUNTIFS( 'Unit-Level Data'!K:K, ">=" & ($Q$2 - 14), 'Unit-Level Data'!K:K, "<=" & ($Q$2 - 7), 'Unit-Level Data'!G:G, 1, 'Unit-Level Data'!B:B, B18 ) -> 0 | M19: =IFERROR(AVERAGEIFS('Unit-Level Data'!O:O,'Unit-Level Data'!K:K,">="&($Q$2-7), 'Unit-Level Data'!K:K,"<="&$Q$2, 'Unit-Level Data'!G:G,1, 'Unit-Level Data'!B:B,B18),"") | N19: =COUNTIFS('Unit-Level Data'!B:B, B18, 'Unit-Level Data'!G:G, 1, 'Unit-Level Data'!L:L, "") -> 0 | O19: =N19-(N19-K19+F19) -> 0 | P19: =IFERROR(AVERAGEIFS('Unit-Level Data'!O:O,'Unit-Level Data'!B:B, B18, 'Unit-Level Data'!G:G, 1, 'Unit-Level Data'!L:L, ""),"") | Q19: =IFERROR(N19/SUMIFS('Unit Mix'!G:G,'Unit Mix'!D:D,1,'Unit Mix'!B:B,B18),"")
B20: =IF(ISBLANK(OFFSET('Rent Comparison'!$A$1,2,8)),"",OFFSET('Rent Comparison'!$A$1,2,8)) | E20: 2 BR | F20: =COUNTIFS('Unit-Level Data'!L:L, ">=" & ($Q$2 - 7), 'Unit-Level Data'!L:L, "<" & $Q$2, 'Unit-Level Data'!G:G, 2, 'Unit-Level Data'!B:B, B18) -> 0 | G20: =COUNTIFS('Unit-Level Data'!L:L, ">=" & ($Q$2 - 7), 'Unit-Level Data'!L:L, "<" & $Q$2, 'Unit-Level Data'!G:G, 2, 'Unit-Level Data'!B:B, B18) - COUNTIFS('Unit-Level Data'!L:L, ">=" & ($Q$2 - 14), 'Unit-Level Data'!L:L, "<=" & ($Q$2 - 7), 'Unit-Level Data'!G:G, 2, 'Unit-Level Data'!B:B, B18) -> 0 | H20: =IFERROR(AVERAGEIFS('Unit-Level Data'!O:O,'Unit-Level Data'!L:L, ">=" & ($Q$2 - 7), 'Unit-Level Data'!L:L, "<" & $Q$2, 'Unit-Level Data'!G:G, 2, 'Unit-Level Data'!B:B, B18),"") | I20: =IFERROR( AVERAGEIFS('Unit-Level Data'!O:O, 'Unit-Level Data'!L:L, ">=" & ($Q$2 - 7), 'Unit-Level Data'!L:L, "<" & $Q$2, 'Unit-Level Data'!G:G, 2, 'Unit-Level Data'!B:B, B18) - AVERAGEIFS('Unit-Level Data'!O:O, 'Unit-Level Data'!L:L, ">=" & ($Q$2 - 14), 'Unit-Level Data'!L:L, "<=" & ($Q$2 - 7), 'Unit-Level Data'!G:G, 2, 'Unit-Level Data'!B:B, B18), 0) -> 0 | J20: =IFERROR(I20/AVERAGEIFS('Unit-Level Data'!O:O, 'Unit-Level Data'!L:L, ">=" & ($Q$2 - 14), 'Unit-Level Data'!L:L, "<=" & ($Q$2 - 7), 'Unit-Level Data'!G:G, 2, 'Unit-Level Data'!B:B, B18),0) -> 0 | K20: =COUNTIFS('Unit-Level Data'!K:K, ">=" & ($Q$2 - 7), 'Unit-Level Data'!K:K, "<" & $Q$2, 'Unit-Level Data'!G:G, 2, 'Unit-Level Data'!B:B, B18) -> 0 | L20: =COUNTIFS( 'Unit-Level Data'!K:K, ">=" & ($Q$2 - 7), 'Unit-Level Data'!K:K, "<" & $Q$2, 'Unit-Level Data'!G:G, 2, 'Unit-Level Data'!B:B, B18 ) - COUNTIFS( 'Unit-Level Data'!K:K, ">=" & ($Q$2 - 14), 'Unit-Level Data'!K:K, "<=" & ($Q$2 - 7), 'Unit-Level Data'!G:G, 2, 'Unit-Level Data'!B:B, B18 ) -> 0 | M20: =IFERROR(AVERAGEIFS('Unit-Level Data'!O:O,'Unit-Level Data'!K:K,">="&($Q$2-7), 'Unit-Level Data'!K:K,"<="&$Q$2, 'Unit-Level Data'!G:G,2, 'Unit-Level Data'!B:B,B18),"") | N20: =COUNTIFS('Unit-Level Data'!B:B, B18, 'Unit-Level Data'!G:G, 2, 'Unit-Level Data'!L:L, "") -> 0 | O20: =N20-(N20-K20+F20) -> 0 | P20: =IFERROR(AVERAGEIFS('Unit-Level Data'!O:O,'Unit-Level Data'!B:B, B18, 'Unit-Level Data'!G:G, 2, 'Unit-Level Data'!L:L, ""),"") | Q20: =IFERROR(N20/SUMIFS('Unit Mix'!G:G,'Unit Mix'!D:D,2,'Unit Mix'!B:B,B18),"")
B21: =IF(ISBLANK(OFFSET('Rent Comparison'!$A$1,3,8)),"",OFFSET('Rent Comparison'!$A$1,3,8)) | E21: 3 BR | F21: =COUNTIFS('Unit-Level Data'!L:L, ">=" & ($Q$2 - 7), 'Unit-Level Data'!L:L, "<" & $Q$2, 'Unit-Level Data'!G:G, 3, 'Unit-Level Data'!B:B, B18) -> 0 | G21: =COUNTIFS('Unit-Level Data'!L:L, ">=" & ($Q$2 - 7), 'Unit-Level Data'!L:L, "<" & $Q$2, 'Unit-Level Data'!G:G, 3, 'Unit-Level Data'!B:B, B18) - COUNTIFS('Unit-Level Data'!L:L, ">=" & ($Q$2 - 14), 'Unit-Level Data'!L:L, "<=" & ($Q$2 - 7), 'Unit-Level Data'!G:G, 3, 'Unit-Level Data'!B:B, B18) -> 0 | H21: =IFERROR(AVERAGEIFS('Unit-Level Data'!O:O,'Unit-Level Data'!L:L, ">=" & ($Q$2 - 7), 'Unit-Level Data'!L:L, "<" & $Q$2, 'Unit-Level Data'!G:G, 3, 'Unit-Level Data'!B:B, B18),"") | I21: =IFERROR( AVERAGEIFS('Unit-Level Data'!O:O, 'Unit-Level Data'!L:L, ">=" & ($Q$2 - 7), 'Unit-Level Data'!L:L, "<" & $Q$2, 'Unit-Level Data'!G:G, 3, 'Unit-Level Data'!B:B, B18) - AVERAGEIFS('Unit-Level Data'!O:O, 'Unit-Level Data'!L:L, ">=" & ($Q$2 - 14), 'Unit-Level Data'!L:L, "<=" & ($Q$2 - 7), 'Unit-Level Data'!G:G, 3, 'Unit-Level Data'!B:B, B18), 0) -> 0 | J21: =IFERROR(I21/AVERAGEIFS('Unit-Level Data'!O:O, 'Unit-Level Data'!L:L, ">=" & ($Q$2 - 14), 'Unit-Level Data'!L:L, "<=" & ($Q$2 - 7), 'Unit-Level Data'!G:G, 3, 'Unit-Level Data'!B:B, B18),0) -> 0 | K21: =COUNTIFS('Unit-Level Data'!K:K, ">=" & ($Q$2 - 7), 'Unit-Level Data'!K:K, "<" & $Q$2, 'Unit-Level Data'!G:G, 3, 'Unit-Level Data'!B:B, B18) -> 0 | L21: =COUNTIFS( 'Unit-Level Data'!K:K, ">=" & ($Q$2 - 7), 'Unit-Level Data'!K:K, "<" & $Q$2, 'Unit-Level Data'!G:G, 3, 'Unit-Level Data'!B:B, B18 ) - COUNTIFS( 'Unit-Level Data'!K:K, ">=" & ($Q$2 - 14), 'Unit-Level Data'!K:K, "<=" & ($Q$2 - 7), 'Unit-Level Data'!G:G, 3, 'Unit-Level Data'!B:B, B18 ) -> 0 | M21: =IFERROR(AVERAGEIFS('Unit-Level Data'!O:O,'Unit-Level Data'!K:K,">="&($Q$2-7), 'Unit-Level Data'!K:K,"<="&$Q$2, 'Unit-Level Data'!G:G,3, 'Unit-Level Data'!B:B,B18),"") | N21: =COUNTIFS('Unit-Level Data'!B:B, B18, 'Unit-Level Data'!G:G, 3, 'Unit-Level Data'!L:L, "") -> 0 | O21: =N21-(N21-K21+F21) -> 0 | P21: =IFERROR(AVERAGEIFS('Unit-Level Data'!O:O,'Unit-Level Data'!B:B, B18, 'Unit-Level Data'!G:G, 3, 'Unit-Level Data'!L:L, ""),"") | Q21: =IFERROR(N21/SUMIFS('Unit Mix'!G:G,'Unit Mix'!D:D,3,'Unit Mix'!B:B,B18),"")
B22: =IF(ISBLANK(OFFSET('Rent Comparison'!$A$1,1,9)),"",OFFSET('Rent Comparison'!$A$1,1,9)) | C22: =IF(ISBLANK(B22),"",IFERROR(INDEX(Specials!B:J,MATCH(B22&" - Active",Specials!I:I,0),2),"")) | E22: Studio | F22: =COUNTIFS('Unit-Level Data'!L:L, ">=" & ($Q$2 - 7), 'Unit-Level Data'!L:L, "<" & $Q$2, 'Unit-Level Data'!G:G, 0, 'Unit-Level Data'!B:B, B22) -> 0 | G22: =COUNTIFS('Unit-Level Data'!L:L, ">=" & ($Q$2 - 7), 'Unit-Level Data'!L:L, "<" & $Q$2, 'Unit-Level Data'!G:G, 0, 'Unit-Level Data'!B:B, B22) - COUNTIFS('Unit-Level Data'!L:L, ">=" & ($Q$2 - 14), 'Unit-Level Data'!L:L, "<=" & ($Q$2 - 7), 'Unit-Level Data'!G:G, 0, 'Unit-Level Data'!B:B, B22) -> 0 | H22: =IFERROR(AVERAGEIFS('Unit-Level Data'!O:O,'Unit-Level Data'!L:L, ">=" & ($Q$2 - 7), 'Unit-Level Data'!L:L, "<" & $Q$2, 'Unit-Level Data'!G:G, 0, 'Unit-Level Data'!B:B, B22),"") | I22: =IFERROR( AVERAGEIFS('Unit-Level Data'!O:O, 'Unit-Level Data'!L:L, ">=" & ($Q$2 - 7), 'Unit-Level Data'!L:L, "<" & $Q$2, 'Unit-Level Data'!G:G, 0, 'Unit-Level Data'!B:B, B22) - AVERAGEIFS('Unit-Level Data'!O:O, 'Unit-Level Data'!L:L, ">=" & ($Q$2 - 14), 'Unit-Level Data'!L:L, "<=" & ($Q$2 - 7), 'Unit-Level Data'!G:G, 0, 'Unit-Level Data'!B:B, B22), 0) -> 0 | J22: =IFERROR(I22/AVERAGEIFS('Unit-Level Data'!O:O, 'Unit-Level Data'!L:L, ">=" & ($Q$2 - 14), 'Unit-Level Data'!L:L, "<=" & ($Q$2 - 7), 'Unit-Level Data'!G:G, 0, 'Unit-Level Data'!B:B, B22),0) -> 0 | K22: =COUNTIFS('Unit-Level Data'!K:K, ">=" & ($Q$2 - 7), 'Unit-Level Data'!K:K, "<" & $Q$2, 'Unit-Level Data'!G:G, 0, 'Unit-Level Data'!B:B, B22) -> 0 | L22: =COUNTIFS( 'Unit-Level Data'!K:K, ">=" & ($Q$2 - 7), 'Unit-Level Data'!K:K, "<" & $Q$2, 'Unit-Level Data'!G:G, 0, 'Unit-Level Data'!B:B, B22 ) - COUNTIFS( 'Unit-Level Data'!K:K, ">=" & ($Q$2 - 14), 'Unit-Level Data'!K:K, "<=" & ($Q$2 - 7), 'Unit-Level Data'!G:G, 0, 'Unit-Level Data'!B:B, B22 ) -> 0 | M22: =IFERROR(AVERAGEIFS('Unit-Level Data'!O:O,'Unit-Level Data'!K:K,">="&($Q$2-7), 'Unit-Level Data'!K:K,"<="&$Q$2, 'Unit-Level Data'!G:G,0, 'Unit-Level Data'!B:B,B22),"") | N22: =COUNTIFS('Unit-Level Data'!B:B, B22, 'Unit-Level Data'!G:G, 0, 'Unit-Level Data'!L:L, "") -> 0 | O22: =N22-(N22-K22+F22) -> 0 | P22: =IFERROR(AVERAGEIFS('Unit-Level Data'!O:O,'Unit-Level Data'!B:B, B22, 'Unit-Level Data'!G:G, 0, 'Unit-Level Data'!L:L, ""),"") | Q22: =IFERROR(N22/SUMIFS('Unit Mix'!G:G,'Unit Mix'!D:D,0,'Unit Mix'!B:B,B22),"")
B23: =IF(ISBLANK(OFFSET('Rent Comps'!$A$1,7,2)),"",OFFSET('Rent Comps'!$A$1,7,2)) | E23: 1 BR | F23: =COUNTIFS('Unit-Level Data'!L:L, ">=" & ($Q$2 - 7), 'Unit-Level Data'!L:L, "<" & $Q$2, 'Unit-Level Data'!G:G, 1, 'Unit-Level Data'!B:B, B22) -> 0 | G23: =COUNTIFS('Unit-Level Data'!L:L, ">=" & ($Q$2 - 7), 'Unit-Level Data'!L:L, "<" & $Q$2, 'Unit-Level Data'!G:G, 1, 'Unit-Level Data'!B:B, B22) - COUNTIFS('Unit-Level Data'!L:L, ">=" & ($Q$2 - 14), 'Unit-Level Data'!L:L, "<=" & ($Q$2 - 7), 'Unit-Level Data'!G:G, 1, 'Unit-Level Data'!B:B, B22) -> 0 | H23: =IFERROR(AVERAGEIFS('Unit-Level Data'!O:O,'Unit-Level Data'!L:L, ">=" & ($Q$2 - 7), 'Unit-Level Data'!L:L, "<" & $Q$2, 'Unit-Level Data'!G:G, 1, 'Unit-Level Data'!B:B, B22),"") | I23: =IFERROR( AVERAGEIFS('Unit-Level Data'!O:O, 'Unit-Level Data'!L:L, ">=" & ($Q$2 - 7), 'Unit-Level Data'!L:L, "<" & $Q$2, 'Unit-Level Data'!G:G, 1, 'Unit-Level Data'!B:B, B22) - AVERAGEIFS('Unit-Level Data'!O:O, 'Unit-Level Data'!L:L, ">=" & ($Q$2 - 14), 'Unit-Level Data'!L:L, "<=" & ($Q$2 - 7), 'Unit-Level Data'!G:G, 1, 'Unit-Level Data'!B:B, B22), 0) -> 0 | J23: =IFERROR(I23/AVERAGEIFS('Unit-Level Data'!O:O, 'Unit-Level Data'!L:L, ">=" & ($Q$2 - 14), 'Unit-Level Data'!L:L, "<=" & ($Q$2 - 7), 'Unit-Level Data'!G:G, 1, 'Unit-Level Data'!B:B, B22),0) -> 0 | K23: =COUNTIFS('Unit-Level Data'!K:K, ">=" & ($Q$2 - 7), 'Unit-Level Data'!K:K, "<" & $Q$2, 'Unit-Level Data'!G:G, 1, 'Unit-Level Data'!B:B, B22) -> 0 | L23: =COUNTIFS( 'Unit-Level Data'!K:K, ">=" & ($Q$2 - 7), 'Unit-Level Data'!K:K, "<" & $Q$2, 'Unit-Level Data'!G:G, 1, 'Unit-Level Data'!B:B, B22 ) - COUNTIFS( 'Unit-Level Data'!K:K, ">=" & ($Q$2 - 14), 'Unit-Level Data'!K:K, "<=" & ($Q$2 - 7), 'Unit-Level Data'!G:G, 1, 'Unit-Level Data'!B:B, B22 ) -> 0 | M23: =IFERROR(AVERAGEIFS('Unit-Level Data'!O:O,'Unit-Level Data'!K:K,">="&($Q$2-7), 'Unit-Level Data'!K:K,"<="&$Q$2, 'Unit-Level Data'!G:G,1, 'Unit-Level Data'!B:B,B22),"") | N23: =COUNTIFS('Unit-Level Data'!B:B, B22, 'Unit-Level Data'!G:G, 1, 'Unit-Level Data'!L:L, "") -> 0 | O23: =N23-(N23-K23+F23) -> 0 | P23: =IFERROR(AVERAGEIFS('Unit-Level Data'!O:O,'Unit-Level Data'!B:B, B22, 'Unit-Level Data'!G:G, 1, 'Unit-Level Data'!L:L, ""),"") | Q23: =IFERROR(N23/SUMIFS('Unit Mix'!G:G,'Unit Mix'!D:D,1,'Unit Mix'!B:B,B22),"")
B24: =IF(ISBLANK(OFFSET('Rent Comparison'!$A$1,2,9)),"",OFFSET('Rent Comparison'!$A$1,2,9)) | E24: 2 BR | F24: =COUNTIFS('Unit-Level Data'!L:L, ">=" & ($Q$2 - 7), 'Unit-Level Data'!L:L, "<" & $Q$2, 'Unit-Level Data'!G:G, 2, 'Unit-Level Data'!B:B, B22) -> 0 | G24: =COUNTIFS('Unit-Level Data'!L:L, ">=" & ($Q$2 - 7), 'Unit-Level Data'!L:L, "<" & $Q$2, 'Unit-Level Data'!G:G, 2, 'Unit-Level Data'!B:B, B22) - COUNTIFS('Unit-Level Data'!L:L, ">=" & ($Q$2 - 14), 'Unit-Level Data'!L:L, "<=" & ($Q$2 - 7), 'Unit-Level Data'!G:G, 2, 'Unit-Level Data'!B:B, B22) -> 0 | H24: =IFERROR(AVERAGEIFS('Unit-Level Data'!O:O,'Unit-Level Data'!L:L, ">=" & ($Q$2 - 7), 'Unit-Level Data'!L:L, "<" & $Q$2, 'Unit-Level Data'!G:G, 2, 'Unit-Level Data'!B:B, B22),"") | I24: =IFERROR( AVERAGEIFS('Unit-Level Data'!O:O, 'Unit-Level Data'!L:L, ">=" & ($Q$2 - 7), 'Unit-Level Data'!L:L, "<" & $Q$2, 'Unit-Level Data'!G:G, 2, 'Unit-Level Data'!B:B, B22) - AVERAGEIFS('Unit-Level Data'!O:O, 'Unit-Level Data'!L:L, ">=" & ($Q$2 - 14), 'Unit-Level Data'!L:L, "<=" & ($Q$2 - 7), 'Unit-Level Data'!G:G, 2, 'Unit-Level Data'!B:B, B22), 0) -> 0 | J24: =IFERROR(I24/AVERAGEIFS('Unit-Level Data'!O:O, 'Unit-Level Data'!L:L, ">=" & ($Q$2 - 14), 'Unit-Level Data'!L:L, "<=" & ($Q$2 - 7), 'Unit-Level Data'!G:G, 2, 'Unit-Level Data'!B:B, B22),0) -> 0 | K24: =COUNTIFS('Unit-Level Data'!K:K, ">=" & ($Q$2 - 7), 'Unit-Level Data'!K:K, "<" & $Q$2, 'Unit-Level Data'!G:G, 2, 'Unit-Level Data'!B:B, B22) -> 0 | L24: =COUNTIFS( 'Unit-Level Data'!K:K, ">=" & ($Q$2 - 7), 'Unit-Level Data'!K:K, "<" & $Q$2, 'Unit-Level Data'!G:G, 2, 'Unit-Level Data'!B:B, B22 ) - COUNTIFS( 'Unit-Level Data'!K:K, ">=" & ($Q$2 - 14), 'Unit-Level Data'!K:K, "<=" & ($Q$2 - 7), 'Unit-Level Data'!G:G, 2, 'Unit-Level Data'!B:B, B22 ) -> 0 | M24: =IFERROR(AVERAGEIFS('Unit-Level Data'!O:O,'Unit-Level Data'!K:K,">="&($Q$2-7), 'Unit-Level Data'!K:K,"<="&$Q$2, 'Unit-Level Data'!G:G,2, 'Unit-Level Data'!B:B,B22),"") | N24: =COUNTIFS('Unit-Level Data'!B:B, B22, 'Unit-Level Data'!G:G, 2, 'Unit-Level Data'!L:L, "") -> 0 | O24: =N24-(N24-K24+F24) -> 0 | P24: =IFERROR(AVERAGEIFS('Unit-Level Data'!O:O,'Unit-Level Data'!B:B, B22, 'Unit-Level Data'!G:G, 2, 'Unit-Level Data'!L:L, ""),"") | Q24: =IFERROR(N24/SUMIFS('Unit Mix'!G:G,'Unit Mix'!D:D,2,'Unit Mix'!B:B,B22),"")
B25: =IF(ISBLANK(OFFSET('Rent Comparison'!$A$1,3,9)),"",OFFSET('Rent Comparison'!$A$1,3,9)) | E25: 3 BR | F25: =COUNTIFS('Unit-Level Data'!L:L, ">=" & ($Q$2 - 7), 'Unit-Level Data'!L:L, "<" & $Q$2, 'Unit-Level Data'!G:G, 3, 'Unit-Level Data'!B:B, B22) -> 0 | G25: =COUNTIFS('Unit-Level Data'!L:L, ">=" & ($Q$2 - 7), 'Unit-Level Data'!L:L, "<" & $Q$2, 'Unit-Level Data'!G:G, 3, 'Unit-Level Data'!B:B, B22) - COUNTIFS('Unit-Level Data'!L:L, ">=" & ($Q$2 - 14), 'Unit-Level Data'!L:L, "<=" & ($Q$2 - 7), 'Unit-Level Data'!G:G, 3, 'Unit-Level Data'!B:B, B22) -> 0 | H25: =IFERROR(AVERAGEIFS('Unit-Level Data'!O:O,'Unit-Level Data'!L:L, ">=" & ($Q$2 - 7), 'Unit-Level Data'!L:L, "<" & $Q$2, 'Unit-Level Data'!G:G, 3, 'Unit-Level Data'!B:B, B22),"") | I25: =IFERROR( AVERAGEIFS('Unit-Level Data'!O:O, 'Unit-Level Data'!L:L, ">=" & ($Q$2 - 7), 'Unit-Level Data'!L:L, "<" & $Q$2, 'Unit-Level Data'!G:G, 3, 'Unit-Level Data'!B:B, B22) - AVERAGEIFS('Unit-Level Data'!O:O, 'Unit-Level Data'!L:L, ">=" & ($Q$2 - 14), 'Unit-Level Data'!L:L, "<=" & ($Q$2 - 7), 'Unit-Level Data'!G:G, 3, 'Unit-Level Data'!B:B, B22), 0) -> 0 | J25: =IFERROR(I25/AVERAGEIFS('Unit-Level Data'!O:O, 'Unit-Level Data'!L:L, ">=" & ($Q$2 - 14), 'Unit-Level Data'!L:L, "<=" & ($Q$2 - 7), 'Unit-Level Data'!G:G, 3, 'Unit-Level Data'!B:B, B22),0) -> 0 | K25: =COUNTIFS('Unit-Level Data'!K:K, ">=" & ($Q$2 - 7), 'Unit-Level Data'!K:K, "<" & $Q$2, 'Unit-Level Data'!G:G, 3, 'Unit-Level Data'!B:B, B22) -> 0 | L25: =COUNTIFS( 'Unit-Level Data'!K:K, ">=" & ($Q$2 - 7), 'Unit-Level Data'!K:K, "<" & $Q$2, 'Unit-Level Data'!G:G, 3, 'Unit-Level Data'!B:B, B22 ) - COUNTIFS( 'Unit-Level Data'!K:K, ">=" & ($Q$2 - 14), 'Unit-Level Data'!K:K, "<=" & ($Q$2 - 7), 'Unit-Level Data'!G:G, 3, 'Unit-Level Data'!B:B, B22 ) -> 0 | M25: =IFERROR(AVERAGEIFS('Unit-Level Data'!O:O,'Unit-Level Data'!K:K,">="&($Q$2-7), 'Unit-Level Data'!K:K,"<="&$Q$2, 'Unit-Level Data'!G:G,3, 'Unit-Level Data'!B:B,B22),"") | N25: =COUNTIFS('Unit-Level Data'!B:B, B22, 'Unit-Level Data'!G:G, 3, 'Unit-Level Data'!L:L, "") -> 0 | O25: =N25-(N25-K25+F25) -> 0 | P25: =IFERROR(AVERAGEIFS('Unit-Level Data'!O:O,'Unit-Level Data'!B:B, B22, 'Unit-Level Data'!G:G, 3, 'Unit-Level Data'!L:L, ""),"") | Q25: =IFERROR(N25/SUMIFS('Unit Mix'!G:G,'Unit Mix'!D:D,3,'Unit Mix'!B:B,B22),"")
B26: =IF(ISBLANK(OFFSET('Rent Comparison'!$A$1,1,10)),"",OFFSET('Rent Comparison'!$A$1,1,10)) | C26: =IF(ISBLANK(B26),"",IFERROR(INDEX(Specials!B:J,MATCH(B26&" - Active",Specials!I:I,0),2),"")) | E26: Studio | F26: =COUNTIFS('Unit-Level Data'!L:L, ">=" & ($Q$2 - 7), 'Unit-Level Data'!L:L, "<" & $Q$2, 'Unit-Level Data'!G:G, 0, 'Unit-Level Data'!B:B, B26) -> 0 | G26: =COUNTIFS('Unit-Level Data'!L:L, ">=" & ($Q$2 - 7), 'Unit-Level Data'!L:L, "<" & $Q$2, 'Unit-Level Data'!G:G, 0, 'Unit-Level Data'!B:B, B26) - COUNTIFS('Unit-Level Data'!L:L, ">=" & ($Q$2 - 14), 'Unit-Level Data'!L:L, "<=" & ($Q$2 - 7), 'Unit-Level Data'!G:G, 0, 'Unit-Level Data'!B:B, B26) -> 0 | H26: =IFERROR(AVERAGEIFS('Unit-Level Data'!O:O,'Unit-Level Data'!L:L, ">=" & ($Q$2 - 7), 'Unit-Level Data'!L:L, "<" & $Q$2, 'Unit-Level Data'!G:G, 0, 'Unit-Level Data'!B:B, B26),"") | I26: =IFERROR( AVERAGEIFS('Unit-Level Data'!O:O, 'Unit-Level Data'!L:L, ">=" & ($Q$2 - 7), 'Unit-Level Data'!L:L, "<" & $Q$2, 'Unit-Level Data'!G:G, 0, 'Unit-Level Data'!B:B, B26) - AVERAGEIFS('Unit-Level Data'!O:O, 'Unit-Level Data'!L:L, ">=" & ($Q$2 - 14), 'Unit-Level Data'!L:L, "<=" & ($Q$2 - 7), 'Unit-Level Data'!G:G, 0, 'Unit-Level Data'!B:B, B26), 0) -> 0 | J26: =IFERROR(I26/AVERAGEIFS('Unit-Level Data'!O:O, 'Unit-Level Data'!L:L, ">=" & ($Q$2 - 14), 'Unit-Level Data'!L:L, "<=" & ($Q$2 - 7), 'Unit-Level Data'!G:G, 0, 'Unit-Level Data'!B:B, B26),0) -> 0 | K26: =COUNTIFS('Unit-Level Data'!K:K, ">=" & ($Q$2 - 7), 'Unit-Level Data'!K:K, "<" & $Q$2, 'Unit-Level Data'!G:G, 0, 'Unit-Level Data'!B:B, B26) -> 0 | L26: =COUNTIFS( 'Unit-Level Data'!K:K, ">=" & ($Q$2 - 7), 'Unit-Level Data'!K:K, "<" & $Q$2, 'Unit-Level Data'!G:G, 0, 'Unit-Level Data'!B:B, B26 ) - COUNTIFS( 'Unit-Level Data'!K:K, ">=" & ($Q$2 - 14), 'Unit-Level Data'!K:K, "<=" & ($Q$2 - 7), 'Unit-Level Data'!G:G, 0, 'Unit-Level Data'!B:B, B26 ) -> 0 | M26: =IFERROR(AVERAGEIFS('Unit-Level Data'!O:O,'Unit-Level Data'!K:K,">="&($Q$2-7), 'Unit-Level Data'!K:K,"<="&$Q$2, 'Unit-Level Data'!G:G,0, 'Unit-Level Data'!B:B,B26),"") | N26: =COUNTIFS('Unit-Level Data'!B:B, B26, 'Unit-Level Data'!G:G, 0, 'Unit-Level Data'!L:L, "") -> 0 | O26: =N26-(N26-K26+F26) -> 0 | P26: =IFERROR(AVERAGEIFS('Unit-Level Data'!O:O,'Unit-Level Data'!B:B, B26, 'Unit-Level Data'!G:G, 0, 'Unit-Level Data'!L:L, ""),"") | Q26: =IFERROR(N26/SUMIFS('Unit Mix'!G:G,'Unit Mix'!D:D,0,'Unit Mix'!B:B,B26),"")
B27: =IF(ISBLANK(OFFSET('Rent Comps'!$A$1,8,2)),"",OFFSET('Rent Comps'!$A$1,8,2)) | E27: 1 BR | F27: =COUNTIFS('Unit-Level Data'!L:L, ">=" & ($Q$2 - 7), 'Unit-Level Data'!L:L, "<" & $Q$2, 'Unit-Level Data'!G:G, 1, 'Unit-Level Data'!B:B, B26) -> 0 | G27: =COUNTIFS('Unit-Level Data'!L:L, ">=" & ($Q$2 - 7), 'Unit-Level Data'!L:L, "<" & $Q$2, 'Unit-Level Data'!G:G, 1, 'Unit-Level Data'!B:B, B26) - COUNTIFS('Unit-Level Data'!L:L, ">=" & ($Q$2 - 14), 'Unit-Level Data'!L:L, "<=" & ($Q$2 - 7), 'Unit-Level Data'!G:G, 1, 'Unit-Level Data'!B:B, B26) -> 0 | H27: =IFERROR(AVERAGEIFS('Unit-Level Data'!O:O,'Unit-Level Data'!L:L, ">=" & ($Q$2 - 7), 'Unit-Level Data'!L:L, "<" & $Q$2, 'Unit-Level Data'!G:G, 1, 'Unit-Level Data'!B:B, B26),"") | I27: =IFERROR( AVERAGEIFS('Unit-Level Data'!O:O, 'Unit-Level Data'!L:L, ">=" & ($Q$2 - 7), 'Unit-Level Data'!L:L, "<" & $Q$2, 'Unit-Level Data'!G:G, 1, 'Unit-Level Data'!B:B, B26) - AVERAGEIFS('Unit-Level Data'!O:O, 'Unit-Level Data'!L:L, ">=" & ($Q$2 - 14), 'Unit-Level Data'!L:L, "<=" & ($Q$2 - 7), 'Unit-Level Data'!G:G, 1, 'Unit-Level Data'!B:B, B26), 0) -> 0 | J27: =IFERROR(I27/AVERAGEIFS('Unit-Level Data'!O:O, 'Unit-Level Data'!L:L, ">=" & ($Q$2 - 14), 'Unit-Level Data'!L:L, "<=" & ($Q$2 - 7), 'Unit-Level Data'!G:G, 1, 'Unit-Level Data'!B:B, B26),0) -> 0 | K27: =COUNTIFS('Unit-Level Data'!K:K, ">=" & ($Q$2 - 7), 'Unit-Level Data'!K:K, "<" & $Q$2, 'Unit-Level Data'!G:G, 1, 'Unit-Level Data'!B:B, B26) -> 0 | L27: =COUNTIFS( 'Unit-Level Data'!K:K, ">=" & ($Q$2 - 7), 'Unit-Level Data'!K:K, "<" & $Q$2, 'Unit-Level Data'!G:G, 1, 'Unit-Level Data'!B:B, B26 ) - COUNTIFS( 'Unit-Level Data'!K:K, ">=" & ($Q$2 - 14), 'Unit-Level Data'!K:K, "<=" & ($Q$2 - 7), 'Unit-Level Data'!G:G, 1, 'Unit-Level Data'!B:B, B26 ) -> 0 | M27: =IFERROR(AVERAGEIFS('Unit-Level Data'!O:O,'Unit-Level Data'!K:K,">="&($Q$2-7), 'Unit-Level Data'!K:K,"<="&$Q$2, 'Unit-Level Data'!G:G,1, 'Unit-Level Data'!B:B,B26),"") | N27: =COUNTIFS('Unit-Level Data'!B:B, B26, 'Unit-Level Data'!G:G, 1, 'Unit-Level Data'!L:L, "") -> 0 | O27: =N27-(N27-K27+F27) -> 0 | P27: =IFERROR(AVERAGEIFS('Unit-Level Data'!O:O,'Unit-Level Data'!B:B, B26, 'Unit-Level Data'!G:G, 1, 'Unit-Level Data'!L:L, ""),"") | Q27: =IFERROR(N27/SUMIFS('Unit Mix'!G:G,'Unit Mix'!D:D,1,'Unit Mix'!B:B,B26),"")
B28: =IF(ISBLANK(OFFSET('Rent Comparison'!$A$1,2,10)),"",OFFSET('Rent Comparison'!$A$1,2,10)) | E28: 2 BR | F28: =COUNTIFS('Unit-Level Data'!L:L, ">=" & ($Q$2 - 7), 'Unit-Level Data'!L:L, "<" & $Q$2, 'Unit-Level Data'!G:G, 2, 'Unit-Level Data'!B:B, B26) -> 0 | G28: =COUNTIFS('Unit-Level Data'!L:L, ">=" & ($Q$2 - 7), 'Unit-Level Data'!L:L, "<" & $Q$2, 'Unit-Level Data'!G:G, 2, 'Unit-Level Data'!B:B, B26) - COUNTIFS('Unit-Level Data'!L:L, ">=" & ($Q$2 - 14), 'Unit-Level Data'!L:L, "<=" & ($Q$2 - 7), 'Unit-Level Data'!G:G, 2, 'Unit-Level Data'!B:B, B26) -> 0 | H28: =IFERROR(AVERAGEIFS('Unit-Level Data'!O:O,'Unit-Level Data'!L:L, ">=" & ($Q$2 - 7), 'Unit-Level Data'!L:L, "<" & $Q$2, 'Unit-Level Data'!G:G, 2, 'Unit-Level Data'!B:B, B26),"") | I28: =IFERROR( AVERAGEIFS('Unit-Level Data'!O:O, 'Unit-Level Data'!L:L, ">=" & ($Q$2 - 7), 'Unit-Level Data'!L:L, "<" & $Q$2, 'Unit-Level Data'!G:G, 2, 'Unit-Level Data'!B:B, B26) - AVERAGEIFS('Unit-Level Data'!O:O, 'Unit-Level Data'!L:L, ">=" & ($Q$2 - 14), 'Unit-Level Data'!L:L, "<=" & ($Q$2 - 7), 'Unit-Level Data'!G:G, 2, 'Unit-Level Data'!B:B, B26), 0) -> 0 | J28: =IFERROR(I28/AVERAGEIFS('Unit-Level Data'!O:O, 'Unit-Level Data'!L:L, ">=" & ($Q$2 - 14), 'Unit-Level Data'!L:L, "<=" & ($Q$2 - 7), 'Unit-Level Data'!G:G, 2, 'Unit-Level Data'!B:B, B26),0) -> 0 | K28: =COUNTIFS('Unit-Level Data'!K:K, ">=" & ($Q$2 - 7), 'Unit-Level Data'!K:K, "<" & $Q$2, 'Unit-Level Data'!G:G, 2, 'Unit-Level Data'!B:B, B26) -> 0 | L28: =COUNTIFS( 'Unit-Level Data'!K:K, ">=" & ($Q$2 - 7), 'Unit-Level Data'!K:K, "<" & $Q$2, 'Unit-Level Data'!G:G, 2, 'Unit-Level Data'!B:B, B26 ) - COUNTIFS( 'Unit-Level Data'!K:K, ">=" & ($Q$2 - 14), 'Unit-Level Data'!K:K, "<=" & ($Q$2 - 7), 'Unit-Level Data'!G:G, 2, 'Unit-Level Data'!B:B, B26 ) -> 0 | M28: =IFERROR(AVERAGEIFS('Unit-Level Data'!O:O,'Unit-Level Data'!K:K,">="&($Q$2-7), 'Unit-Level Data'!K:K,"<="&$Q$2, 'Unit-Level Data'!G:G,2, 'Unit-Level Data'!B:B,B26),"") | N28: =COUNTIFS('Unit-Level Data'!B:B, B26, 'Unit-Level Data'!G:G, 2, 'Unit-Level Data'!L:L, "") -> 0 | O28: =N28-(N28-K28+F28) -> 0 | P28: =IFERROR(AVERAGEIFS('Unit-Level Data'!O:O,'Unit-Level Data'!B:B, B26, 'Unit-Level Data'!G:G, 2, 'Unit-Level Data'!L:L, ""),"") | Q28: =IFERROR(N28/SUMIFS('Unit Mix'!G:G,'Unit Mix'!D:D,2,'Unit Mix'!B:B,B26),"")
B29: =IF(ISBLANK(OFFSET('Rent Comparison'!$A$1,3,10)),"",OFFSET('Rent Comparison'!$A$1,3,10)) | E29: 3 BR | F29: =COUNTIFS('Unit-Level Data'!L:L, ">=" & ($Q$2 - 7), 'Unit-Level Data'!L:L, "<" & $Q$2, 'Unit-Level Data'!G:G, 3, 'Unit-Level Data'!B:B, B26) -> 0 | G29: =COUNTIFS('Unit-Level Data'!L:L, ">=" & ($Q$2 - 7), 'Unit-Level Data'!L:L, "<" & $Q$2, 'Unit-Level Data'!G:G, 3, 'Unit-Level Data'!B:B, B26) - COUNTIFS('Unit-Level Data'!L:L, ">=" & ($Q$2 - 14), 'Unit-Level Data'!L:L, "<=" & ($Q$2 - 7), 'Unit-Level Data'!G:G, 3, 'Unit-Level Data'!B:B, B26) -> 0 | H29: =IFERROR(AVERAGEIFS('Unit-Level Data'!O:O,'Unit-Level Data'!L:L, ">=" & ($Q$2 - 7), 'Unit-Level Data'!L:L, "<" & $Q$2, 'Unit-Level Data'!G:G, 3, 'Unit-Level Data'!B:B, B26),"") | I29: =IFERROR( AVERAGEIFS('Unit-Level Data'!O:O, 'Unit-Level Data'!L:L, ">=" & ($Q$2 - 7), 'Unit-Level Data'!L:L, "<" & $Q$2, 'Unit-Level Data'!G:G, 3, 'Unit-Level Data'!B:B, B26) - AVERAGEIFS('Unit-Level Data'!O:O, 'Unit-Level Data'!L:L, ">=" & ($Q$2 - 14), 'Unit-Level Data'!L:L, "<=" & ($Q$2 - 7), 'Unit-Level Data'!G:G, 3, 'Unit-Level Data'!B:B, B26), 0) -> 0 | J29: =IFERROR(I29/AVERAGEIFS('Unit-Level Data'!O:O, 'Unit-Level Data'!L:L, ">=" & ($Q$2 - 14), 'Unit-Level Data'!L:L, "<=" & ($Q$2 - 7), 'Unit-Level Data'!G:G, 3, 'Unit-Level Data'!B:B, B26),0) -> 0 | K29: =COUNTIFS('Unit-Level Data'!K:K, ">=" & ($Q$2 - 7), 'Unit-Level Data'!K:K, "<" & $Q$2, 'Unit-Level Data'!G:G, 3, 'Unit-Level Data'!B:B, B26) -> 0 | L29: =COUNTIFS( 'Unit-Level Data'!K:K, ">=" & ($Q$2 - 7), 'Unit-Level Data'!K:K, "<" & $Q$2, 'Unit-Level Data'!G:G, 3, 'Unit-Level Data'!B:B, B26 ) - COUNTIFS( 'Unit-Level Data'!K:K, ">=" & ($Q$2 - 14), 'Unit-Level Data'!K:K, "<=" & ($Q$2 - 7), 'Unit-Level Data'!G:G, 3, 'Unit-Level Data'!B:B, B26 ) -> 0 | M29: =IFERROR(AVERAGEIFS('Unit-Level Data'!O:O,'Unit-Level Data'!K:K,">="&($Q$2-7), 'Unit-Level Data'!K:K,"<="&$Q$2, 'Unit-Level Data'!G:G,3, 'Unit-Level Data'!B:B,B26),"") | N29: =COUNTIFS('Unit-Level Data'!B:B, B26, 'Unit-Level Data'!G:G, 3, 'Unit-Level Data'!L:L, "") -> 0 | O29: =N29-(N29-K29+F29) -> 0 | P29: =IFERROR(AVERAGEIFS('Unit-Level Data'!O:O,'Unit-Level Data'!B:B, B26, 'Unit-Level Data'!G:G, 3, 'Unit-Level Data'!L:L, ""),"") | Q29: =IFERROR(N29/SUMIFS('Unit Mix'!G:G,'Unit Mix'!D:D,3,'Unit Mix'!B:B,B26),"")
B30: =IF(ISBLANK(OFFSET('Rent Comparison'!$A$1,1,11)),"",OFFSET('Rent Comparison'!$A$1,1,11)) | C30: =IF(ISBLANK(B30),"",IFERROR(INDEX(Specials!B:J,MATCH(B30&" - Active",Specials!I:I,0),2),"")) | E30: Studio | F30: =COUNTIFS('Unit-Level Data'!L:L, ">=" & ($Q$2 - 7), 'Unit-Level Data'!L:L, "<" & $Q$2, 'Unit-Level Data'!G:G, 0, 'Unit-Level Data'!B:B, B30) -> 0 | G30: =COUNTIFS('Unit-Level Data'!L:L, ">=" & ($Q$2 - 7), 'Unit-Level Data'!L:L, "<" & $Q$2, 'Unit-Level Data'!G:G, 0, 'Unit-Level Data'!B:B, B30) - COUNTIFS('Unit-Level Data'!L:L, ">=" & ($Q$2 - 14), 'Unit-Level Data'!L:L, "<=" & ($Q$2 - 7), 'Unit-Level Data'!G:G, 0, 'Unit-Level Data'!B:B, B30) -> 0 | H30: =IFERROR(AVERAGEIFS('Unit-Level Data'!O:O,'Unit-Level Data'!L:L, ">=" & ($Q$2 - 7), 'Unit-Level Data'!L:L, "<" & $Q$2, 'Unit-Level Data'!G:G, 0, 'Unit-Level Data'!B:B, B30),"") | I30: =IFERROR( AVERAGEIFS('Unit-Level Data'!O:O, 'Unit-Level Data'!L:L, ">=" & ($Q$2 - 7), 'Unit-Level Data'!L:L, "<" & $Q$2, 'Unit-Level Data'!G:G, 0, 'Unit-Level Data'!B:B, B30) - AVERAGEIFS('Unit-Level Data'!O:O, 'Unit-Level Data'!L:L, ">=" & ($Q$2 - 14), 'Unit-Level Data'!L:L, "<=" & ($Q$2 - 7), 'Unit-Level Data'!G:G, 0, 'Unit-Level Data'!B:B, B30), 0) -> 0 | J30: =IFERROR(I30/AVERAGEIFS('Unit-Level Data'!O:O, 'Unit-Level Data'!L:L, ">=" & ($Q$2 - 14), 'Unit-Level Data'!L:L, "<=" & ($Q$2 - 7), 'Unit-Level Data'!G:G, 0, 'Unit-Level Data'!B:B, B30),0) -> 0 | K30: =COUNTIFS('Unit-Level Data'!K:K, ">=" & ($Q$2 - 7), 'Unit-Level Data'!K:K, "<" & $Q$2, 'Unit-Level Data'!G:G, 0, 'Unit-Level Data'!B:B, B30) -> 0 | L30: =COUNTIFS( 'Unit-Level Data'!K:K, ">=" & ($Q$2 - 7), 'Unit-Level Data'!K:K, "<" & $Q$2, 'Unit-Level Data'!G:G, 0, 'Unit-Level Data'!B:B, B30 ) - COUNTIFS( 'Unit-Level Data'!K:K, ">=" & ($Q$2 - 14), 'Unit-Level Data'!K:K, "<=" & ($Q$2 - 7), 'Unit-Level Data'!G:G, 0, 'Unit-Level Data'!B:B, B30 ) -> 0 | M30: =IFERROR(AVERAGEIFS('Unit-Level Data'!O:O,'Unit-Level Data'!K:K,">="&($Q$2-7), 'Unit-Level Data'!K:K,"<="&$Q$2, 'Unit-Level Data'!G:G,0, 'Unit-Level Data'!B:B,B30),"") | N30: =COUNTIFS('Unit-Level Data'!B:B, B30, 'Unit-Level Data'!G:G, 0, 'Unit-Level Data'!L:L, "") -> 0 | O30: =N30-(N30-K30+F30) -> 0 | P30: =IFERROR(AVERAGEIFS('Unit-Level Data'!O:O,'Unit-Level Data'!B:B, B30, 'Unit-Level Data'!G:G, 0, 'Unit-Level Data'!L:L, ""),"") | Q30: =IFERROR(N30/SUMIFS('Unit Mix'!G:G,'Unit Mix'!D:D,0,'Unit Mix'!B:B,B30),"")
