Workbook

Sheet Pro-forma
B2: Name: Cherry Commons
B3: Address: 1718 North Sydenham Street Philadelphia, PA 19121
G4: Last Updated: | H4: 46056
B6: Project Summary
B7: Year Built | D7: 1950
B8: Lot Size
B9: Building Size
B10: Ask Price
B11: Offer Price | D11: 6200000
B12: Occupancy Rate | D12: 96.42
B13: Total Apartment Units | D13: 28
B14: Total Current Retal Units | D14: 0
B15: Total Parking Spaces | D15: -
B18: Residential Rent Roll | F18: 2025 | G18: 2026
B19: Unit Types | C19: # Units | D19: Bedroom | E19: SQF | F19: As-is rent | G19: Growth | H19: As-is Rent | I19: Projected Rent
B20: 1B | C20: 9 | D20: 1 | E20: 540 | F20: 1490 | G20: 1500 | H20: =F20*12*C20 -> 160920 | I20: =G20*12*C20 -> 162000
B21: 2B | C21: 15 | D21: 2 | E21: 840 | F21: 1850 | G21: 1990 | H21: =F21*12*C21 -> 333000 | I21: =G21*12*C21 -> 358200
B22: 2B Deluxe | C22: 3 | D22: 2 | F22: 1950 | G22: 2150 | H22: =F22*12*C22 -> 70200 | I22: =G22*12*C22 -> 77400
B23: Total/average | C23: =C20+#REF!+C22 -> #REF! | H23: =SUM(H20:H22) -> 564120 | I23: =SUM(I20:I22) -> 597600
B27: ASSUMPTIONS | F27: Tax Assessments
B28: Income
B29: Residential market annual rent growth | D29: 0.03 | F29: Property
B31: Expenses
B32: Operating expenses growth rates | D32: 0.03
B33: Property taxes growth rates | D33: 0.03 | F33: Total | G33: =SUM(G30:G32) -> 0
B36: Exhibit 1 Meadow Lane Projection
B37: Pro Forma
B38: Year | E38: NOV2023-OCT2024 | F38: NOV2024-OCT2025 | G38: NOV2025-OCT2026 | H38: NOV2026-OCT2027 | I38: NOV2027-OCT2028 | J38: NOV2028-OCT2029 | K38: NOV2029-OCT2030
B40: REVENUE | C40: Stabilized | D40: Per Unit
B41: Rent Income | D41: =G41/28 -> 21342.857 | E41: =F41 -> 536297.82 | F41: =SUM('T12'!N9:Y9) -> 536297.82 | G41: =I23 -> 597600 | H41: =I23 -> 597600 | I41: =H41*1.04 -> 621504 | J41: =I41*1.04 -> 646364.16 | K41: =J41*1.04 -> 672218.73
B42: Other Rental Income | D42: =G42/28 -> 45.620536 | E42: =SUM('T12'!B10:M10) -> 2554.75 | F42: =SUM('T12'!N10:Y10) -> 0 | G42: =AVERAGE(E42:F42) -> 1277.375 | H42: =G42*1.03 -> 1315.6962 | I42: =H42*1.03 -> 1355.1671 | J42: =I42*1.03 -> 1395.8222 | K42: =J42*1.03 -> 1437.6968
B43: Application Fee Income | D43: =G43/28 -> 35.625 | E43: =SUM('T12'!B11:M11) -> 1015 | F43: =SUM('T12'!N11:Y11) -> 980 | G43: =AVERAGE(E43:F43) -> 997.5 | H43: =G43*1.03 -> 1027.425 | I43: =H43*1.03 -> 1058.2477 | J43: =I43*1.03 -> 1089.9952 | K43: =J43*1.03 -> 1122.695
B44: NSF Fees Collected | D44: =G44/28 -> 0.71428571 | E44: =SUM('T12'!B12:M12) -> 5 | F44: =SUM('T12'!N12:Y12) -> 35 | G44: =AVERAGE(E44:F44) -> 20 | H44: =G44*1.03 -> 20.6 | I44: =H44*1.03 -> 21.218 | J44: =I44*1.03 -> 21.85454 | K44: =J44*1.03 -> 22.510176
B45: Late Fee | D45: =G45/28 -> 107.36232 | E45: =SUM('T12'!B13:M13) -> 3554.29 | F45: =SUM('T12'!N13:Y13) -> 2458 | G45: =AVERAGE(E45:F45) -> 3006.145 | H45: =G45*1.03 -> 3096.3293 | I45: =H45*1.03 -> 3189.2192 | J45: =I45*1.03 -> 3284.8958 | K45: =J45*1.03 -> 3383.4427
B46: Pet Fee | D46: =G46/28 -> 14.732143 | E46: =SUM('T12'!B14:M14) -> 825 | F46: =SUM('T12'!N14:Y14) -> 0 | G46: =AVERAGE(E46:F46) -> 412.5 | H46: =G46*1.03 -> 424.875 | I46: =H46*1.03 -> 437.62125 | J46: =I46*1.03 -> 450.74989 | K46: =J46*1.03 -> 464.27238
B47: Furniture Charge | D47: =G47/28 -> 23.214286 | E47: =SUM('T12'!B15:M15) -> 400 | F47: =SUM('T12'!N15:Y15) -> 900 | G47: =AVERAGE(E47:F47) -> 650 | H47: =G47*1.03 -> 669.5 | I47: =H47*1.03 -> 689.585 | J47: =I47*1.03 -> 710.27255 | K47: =J47*1.03 -> 731.58073
B48: Laundry Income | D48: =G48/28 -> 75.001786 | E48: =SUM('T12'!B16:M16) -> 2745.83 | F48: =SUM('T12'!N16:Y16) -> 1454.27 | G48: =AVERAGE(E48:F48) -> 2100.05 | H48: =G48*1.03 -> 2163.0515 | I48: =H48*1.03 -> 2227.943 | J48: =I48*1.03 -> 2294.7813 | K48: =J48*1.03 -> 2363.6248
B49: Insurance Services | D49: =G49/28 -> 22.529464 | E49: =SUM('T12'!B17:M17) -> 608.46 | F49: =SUM('T12'!N17:Y17) -> 653.19 | G49: =AVERAGE(E49:F49) -> 630.825 | H49: =G49*1.03 -> 649.74975 | I49: =H49*1.03 -> 669.24224 | J49: =I49*1.03 -> 689.31951 | K49: =J49*1.03 -> 709.9991
B50: Utility Reimbursement Fee | D50: =G50/28 -> 6.2916071 | E50: =SUM('T12'!B18:M18) -> 352.33 | F50: =SUM('T12'!N18:Y18) -> 0 | G50: =AVERAGE(E50:F50) -> 176.165 | H50: =G50*1.03 -> 181.44995 | I50: =H50*1.03 -> 186.89345 | J50: =I50*1.03 -> 192.50025 | K50: =J50*1.03 -> 198.27526
B51: Concessions | D51: =G51/28 -> -129.94839 | E51: =SUM('T12'!B19:M19) -> -7277.11 | F51: =SUM('T12'!N19:Y19) -> 0 | G51: =AVERAGE(E51:F51) -> -3638.555 | H51: =G51*1.03 -> -3747.7117 | I51: =H51*1.03 -> -3860.143 | J51: =I51*1.03 -> -3975.9473 | K51: =J51*1.03 -> -4095.2257
...

Sheet T12
A1: 12 Months Cash Flow Statement
A2: Cherry Commons - 1718 N Sydenham
A3: Period = Nov 2023-Oct 2025
A4: Book = Cash
A5: ACCOUNT | B5: 45231 | C5: 45261 | D5: 45292 | E5: 45323 | F5: 45352 | G5: 45383 | H5: 45413 | I5: 45444 | J5: 45474 | K5: 45505 | L5: 45536 | M5: 45566 | N5: 45597 | O5: 45627 | P5: 45658 | Q5: 45689 | R5: 45717 | S5: 45748 | T5: 45778 | U5: 45809 | V5: 45839 | W5: 45870 | X5: 45901 | Y5: 45931 | Z5: Total
A6: INCOME
A7: REVENUE
A8: RENTS
A9: Rent Income | B9: 537471.3 | C9: -12228.5 | D9: 50194.83 | E9: 51857.75 | F9: 44591 | G9: 52882.13 | H9: 46652 | I9: 40199 | J9: 28967.22 | K9: 38029.72 | L9: 40731.5 | M9: 44850.25 | N9: 42684.25 | O9: 54771.89 | P9: 48759.5 | Q9: 43993.25 | R9: 44925 | S9: 48759.25 | T9: 42258.39 | U9: 44938.5 | V9: 51607.03 | W9: 26576.94 | X9: 41964.04 | Y9: 45059.78 | Z9: 1500496
A10: Other Rental Income | B10: 500 | C10: 2054.75 | D10: 0 | E10: 0 | F10: 0 | G10: 0 | H10: 0 | I10: 0 | J10: 0 | K10: 0 | L10: 0 | M10: 0 | N10: 200 | O10: -200 | P10: 0 | Q10: 0 | R10: 0 | S10: 0 | T10: 0 | U10: 0 | V10: 0 | W10: 0 | X10: 0 | Y10: 0 | Z10: 2554.75
A11: Application Fee Income | B11: 0 | C11: 0 | D11: 70 | E11: 385 | F11: 175 | G11: 140 | H11: 0 | I11: 140 | J11: 105 | K11: 0 | L11: 0 | M11: 0 | N11: 35 | O11: 35 | P11: 0 | Q11: 140 | R11: 175 | S11: 35 | T11: 210 | U11: 245 | V11: 105 | W11: 0 | X11: 0 | Y11: 0 | Z11: 1995
A12: NSF Fees Collected | B12: 0 | C12: 0 | D12: 0 | E12: 0 | F12: 0 | G12: 0 | H12: 0 | I12: 0 | J12: 0 | K12: 0 | L12: 0 | M12: 5 | N12: 0 | O12: 0 | P12: 0 | Q12: -35 | R12: 35 | S12: 0 | T12: 0 | U12: 35 | V12: 0 | W12: 0 | X12: 0 | Y12: 0 | Z12: 40
A13: Late Fee | B13: 48.02 | C13: -48.02 | D13: 245.79 | E13: 50 | F13: 659.15 | G13: 480.25 | H13: 448.3 | I13: 454 | J13: 489.3 | K13: 275 | L13: 380 | M13: 72.5 | N13: 190 | O13: 242.5 | P13: 322.5 | Q13: 195 | R13: 220 | S13: 290 | T13: 92.5 | U13: 392.5 | V13: 152.5 | W13: 0 | X13: 175.5 | Y13: 185 | Z13: 6012.29
A14: Pet Fee | B14: 585 | C14: -40 | D14: 40 | E14: 40 | F14: 40 | G14: 40 | H14: 40 | I14: 40 | J14: 40 | K14: 0 | L14: 0 | M14: 0 | N14: 0 | O14: 0 | P14: 0 | Q14: 0 | R14: 0 | S14: 0 | T14: 0 | U14: 0 | V14: 0 | W14: 0 | X14: 0 | Y14: 0 | Z14: 825
A15: Furniture Charge | B15: 0 | C15: 0 | D15: 0 | E15: 0 | F15: 0 | G15: 0 | H15: 0 | I15: 0 | J15: 100 | K15: 100 | L15: 100 | M15: 100 | N15: 100 | O15: 100 | P15: 100 | Q15: 100 | R15: 100 | S15: 100 | T15: 100 | U15: 100 | V15: 100 | W15: 0 | X15: 0 | Y15: 0 | Z15: 1300
A16: Laundry Income | B16: 1147.5 | C16: 360.74 | D16: 156.96 | E16: 46.98 | F16: 186.57 | G16: 175.15 | H16: 217.25 | I16: 175.85 | J16: 0 | K16: 0 | L16: 86.45 | M16: 192.38 | N16: 294.97 | O16: 202.85 | P16: 0 | Q16: 288.46 | R16: 127.48 | S16: 0 | T16: 0 | U16: 152.61 | V16: 43.74 | W16: 0 | X16: 107.81 | Y16: 236.35 | Z16: 4200.1
A17: Insurance Services | B17: 181 | C17: -48 | D17: 76 | E17: 47.5 | F17: 66.5 | G17: 66.5 | H17: 57 | I17: 57 | J17: 38 | K17: 28.96 | L17: 19 | M17: 19 | N17: 9.5 | O17: 9.5 | P17: 9.5 | Q17: 9.5 | R17: 9.5 | S17: 9.5 | T17: 9.5 | U17: 9.5 | V17: 9.5 | W17: 0 | X17: 316.45 | Y17: 251.24 | Z17: 1261.65
A18: Utility Reimbursement Fee | B18: 352.33 | C18: 0 | D18: 0 | E18: 0 | F18: 0 | G18: 0 | H18: 0 | I18: 0 | J18: 0 | K18: 0 | L18: 0 | M18: 0 | N18: 0 | O18: 0 | P18: 0 | Q18: 0 | R18: 0 | S18: 0 | T18: 0 | U18: 0 | V18: 0 | W18: 0 | X18: 0 | Y18: 0 | Z18: 352.33
A19: Concessions | B19: -7277.11 | C19: 0 | D19: 0 | E19: 0 | F19: 0 | G19: 0 | H19: 0 | I19: 0 | J19: 0 | K19: 0 | L19: 0 | M19: 0 | N19: 0 | O19: 0 | P19: 0 | Q19: 0 | R19: 0 | S19: 0 | T19: 0 | U19: 0 | V19: 0 | W19: 0 | X19: 0 | Y19: 0 | Z19: -7277.11
A20: TOTAL RENTS | B20: 533008.04 | C20: -9949.03 | D20: 50783.58 | E20: 52427.23 | F20: 45718.22 | G20: 53784.03 | H20: 47414.55 | I20: 41065.85 | J20: 29739.52 | K20: 38433.68 | L20: 41316.95 | M20: 45239.13 | N20: 43513.72 | O20: 55161.74 | P20: 49191.5 | Q20: 44691.21 | R20: 45591.98 | S20: 49193.75 | T20: 42670.39 | U20: 45873.11 | V20: 52017.77 | W20: 26576.94 | X20: 42563.8 | Y20: 45732.37 | Z20: 1511760
A21: MANAGEMENT INCOME
A22: Maintenance Labor Fee Income and Materials Reimbursement | B22: 100 | C22: -100 | D22: 0 | E22: 0 | F22: 0 | G22: 0 | H22: 0 | I22: 0 | J22: 0 | K22: 0 | L22: 0 | M22: 0 | N22: 0 | O22: 0 | P22: 0 | Q22: 0 | R22: 0 | S22: 0 | T22: 0 | U22: 0 | V22: 0 | W22: 0 | X22: 0 | Y22: 0 | Z22: 0
A23: Prepaid Rent | B23: 14622.75 | C23: -14622.75 | D23: -5912.5 | E23: 3363.5 | F23: -657 | G23: -515 | H23: -70 | I23: -3434.5 | J23: -3995 | K23: 1630 | L23: 875 | M23: 450 | N23: -1325 | O23: 1905 | P23: -1905 | Q23: -820.25 | R23: 929.75 | S23: 1029 | T23: 50 | U23: -1768.5 | V23: 1007.25 | W23: 369.75 | X23: 392.25 | Y23: 0 | Z23: -8401.25
A24: TOTAL MANAGEMENT INCOME | B24: 14722.75 | C24: -14722.75 | D24: -5912.5 | E24: 3363.5 | F24: -657 | G24: -515 | H24: -70 | I24: -3434.5 | J24: -3995 | K24: 1630 | L24: 875 | M24: 450 | N24: -1325 | O24: 1905 | P24: -1905 | Q24: -820.25 | R24: 929.75 | S24: 1029 | T24: 50 | U24: -1768.5 | V24: 1007.25 | W24: 369.75 | X24: 392.25 | Y24: 0 | Z24: -8401.25
A25: FEES
A26: Miscellaneous Income | B26: 0.23 | C26: -26468.13 | D26: 0 | E26: 0 | F26: 0 | G26: 0 | H26: 0 | I26: 0 | J26: 0 | K26: 0 | L26: 0 | M26: 0 | N26: 0 | O26: 0 | P26: 0 | Q26: 0 | R26: 0 | S26: 0 | T26: 0 | U26: 0 | V26: 0 | W26: 0 | X26: 0 | Y26: 0 | Z26: -26467.9
A27: TOTAL FEES | B27: 0.23 | C27: -26468.13 | D27: 0 | E27: 0 | F27: 0 | G27: 0 | H27: 0 | I27: 0 | J27: 0 | K27: 0 | L27: 0 | M27: 0 | N27: 0 | O27: 0 | P27: 0 | Q27: 0 | R27: 0 | S27: 0 | T27: 0 | U27: 0 | V27: 0 | W27: 0 | X27: 0 | Y27: 0 | Z27: -26467.9
A28: TOTAL REVENUE | B28: 547731.02 | C28: -51139.91 | D28: 44871.08 | E28: 55790.73 | F28: 45061.22 | G28: 53269.03 | H28: 47344.55 | I28: 37631.35 | J28: 25744.52 | K28: 40063.68 | L28: 42191.95 | M28: 45689.13 | N28: 42188.72 | O28: 57066.74 | P28: 47286.5 | Q28: 43870.96 | R28: 46521.73 | S28: 50222.75 | T28: 42720.39 | U28: 44104.61 | V28: 53025.02 | W28: 26946.69 | X28: 42956.05 | Y28: 45732.37 | Z28: 1476890.9
A29: EXPENSES
A30: CLEANING AND JANITORIAL EXPENSE
A31: Cleaning and Janitorial Expense | B31: 1075 | C31: 0 | D31: 200 | E31: 0 | F31: 0 | G31: 0 | H31: 0 | I31: 200 | J31: 0 | K31: 0 | L31: 0 | M31: 0 | N31: 0 | O31: 0 | P31: 0 | Q31: 0 | R31: 0 | S31: 0 | T31: 0 | U31: 0 | V31: 0 | W31: 2862 | X31: 0 | Y31: 0 | Z31: 4337
A32: Maintenance Labor Expense | B32: 185 | C32: -150 | D32: 0 | E32: 0 | F32: 0 | G32: 0 | H32: 0 | I32: 55 | J32: 0 | K32: 0 | L32: 0 | M32: 0 | N32: -55 | O32: 0 | P32: 55 | Q32: 0 | R32: 0 | S32: 0 | T32: 0 | U32: 0 | V32: 0 | W32: 0 | X32: 0 | Y32: 0 | Z32: 90
A33: Garbage and Recycling | B33: 4433.98 | C33: 0 | D33: 948.65 | E33: 0 | F33: -1013.76 | G33: 0 | H33: 2111.69 | I33: 2125.68 | J33: 527.94 | K33: 489.5 | L33: 1753.94 | M33: 97.4 | N33: 621.66 | O33: 0 | P33: 1243.32 | Q33: 621.66 | R33: 621.66 | S33: 621.66 | T33: 621.66 | U33: 621.66 | V33: 621.66 | W33: 621.66 | X33: 621.66 | Y33: 1027.08 | Z33: 19340.36
A34: Pest control | B34: 2359.8 | C34: 0 | D34: 988.2 | E34: 0 | F34: 0 | G34: 378 | H34: 189 | I34: 567 | J34: 0 | K34: 0 | L34: 0 | M34: 0 | N34: 0 | O34: 0 | P34: 0 | Q34: 3213 | R34: 0 | S34: 0 | T34: 0 | U34: 0 | V34: 0 | W34: 0 | X34: 1323 | Y34: 189 | Z34: 9207
A35: TOTAL CLEANING AND JANITORIAL EXPENSE | B35: 8053.78 | C35: -150 | D35: 2136.85 | E35: 0 | F35: -1013.76 | G35: 378 | H35: 2300.69 | I35: 2947.68 | J35: 527.94 | K35: 489.5 | L35: 1753.94 | M35: 97.4 | N35: 566.66 | O35: 0 | P35: 1298.32 | Q35: 3834.66 | R35: 621.66 | S35: 621.66 | T35: 621.66 | U35: 621.66 | V35: 621.66 | W35: 3483.66 | X35: 1944.66 | Y35: 1216.08 | Z35: 32974.36
A36: INSURANCE
A37: Property Insurance | B37: 19020 | C37: -1585 | D37: 0 | E37: 0 | F37: 0 | G37: 0 | H37: 5183.82 | I37: 1587 | J37: 0 | K37: 0 | L37: 0 | M37: 0 | N37: 0 | O37: 6911.76 | P37: 0 | Q37: 0 | R37: 0 | S37: 0 | T37: 0 | U37: 36362.63 | V37: 0 | W37: 0 | X37: 0 | Y37: 0 | Z37: 67480.21
A38: Insurance - Other | B38: 0 | C38: 0 | D38: 0 | E38: 0 | F38: 6911.76 | G38: 0 | H38: 0 | I38: 0 | J38: 0 | K38: 0 | L38: 0 | M38: 0 | N38: 0 | O38: -6911.76 | P38: 0 | Q38: 0 | R38: 0 | S38: 0 | T38: 0 | U38: 0 | V38: 0 | W38: 0 | X38: 0 | Y38: 0 | Z38: 0
A39: TOTAL INSURANCE | B39: 19020 | C39: -1585 | D39: 0 | E39: 0 | F39: 6911.76 | G39: 0 | H39: 5183.82 | I39: 1587 | J39: 0 | K39: 0 | L39: 0 | M39: 0 | N39: 0 | O39: 0 | P39: 0 | Q39: 0 | R39: 0 | S39: 0 | T39: 0 | U39: 36362.63 | V39: 0 | W39: 0 | X39: 0 | Y39: 0 | Z39: 67480.21
A40: LEGAL AND OTHER PROFESSIONAL FEES
...

Sheet RR
A1: Rent Roll
A2: Property = Cherry Commons - 1718 N Sydenham
A3: As Of = 11/12/2025
A4: Month = 11/2025
A5: Unit | B5: Unit | C5: Tenant Name | D5: Actual | E5: Actual Rent | F5: Tenant | G5: Other | H5: Misc | I5: Misc | J5: Move In | K5: Lease | L5: Move Out | M5: Balance
B6: SqFt | D6: Rent | E6: per Sqft | F6: Deposit | G6: Deposit | I6: per Sqft | K6: Expiration
A7: Current/Notice/Vacant Tenants
A8: 1A | B8: 540 | C8: Adam Ha | D8: 1450 | E8: 2.69 | F8: 0 | G8: 1450 | H8: 0 | I8: 0 | J8: 45870 | K8: 46234 | M8: 0
A9: 1B | B9: 840 | C9: Wenjie Shen | D9: 1850 | E9: 2.2 | F9: 0 | G9: 3700 | H9: 0 | I9: 0 | J9: 45884 | K9: 46234 | M9: 0
A10: 1C | B10: 540 | C10: Fiona Kwok | D10: 1350 | E10: 2.5 | F10: 0 | G10: 1350 | H10: 0 | I10: 0 | J10: 45873 | K10: 46237 | M10: 0
A11: 1D | B11: 540 | C11: Jake Naese | D11: 1450 | E11: 2.69 | F11: 0 | G11: 1450 | H11: 0 | I11: 0 | J11: 45873 | K11: 46234 | M11: 0
A12: 1E | B12: 840 | C12: OCCUPIED | D12: 1850 | E12: 0 | F12: 0 | G12: 0 | H12: 0 | I12: 0 | M12: 0
A13: 1F | B13: 840 | C13: Brian ODell | D13: 1850 | E13: 2.2 | F13: 0 | G13: 1850 | H13: 0 | I13: 0 | J13: 45474 | K13: 46234 | M13: 0
A14: 2A | B14: 840 | C14: Zhongying Huang | D14: 1850 | E14: 2.2 | F14: 0 | G14: 3700 | H14: 20 | I14: 0.02 | J14: 45884 | K14: 46234 | M14: 0
A15: 2B | B15: 840 | C15: Shimin Yang | D15: 1850 | E15: 2.2 | F15: 0 | G15: 3700 | H15: 20 | I15: 0.02 | J15: 45873 | K15: 46234 | M15: 0
A16: 2C | B16: 540 | C16: You Wang | D16: 1450 | E16: 2.69 | F16: 0 | G16: 2900 | H16: 20 | I16: 0.04 | J16: 45883 | K16: 46234 | M16: 0
A17: 2D | B17: 540 | C17: Justin Ok | D17: 1450 | E17: 2.69 | F17: 0 | G17: 1375 | H17: 20 | I17: 0.04 | J17: 45508 | K17: 46234 | M17: 0
A18: 2E | B18: 840 | C18: Nicholas Afanassiev | D18: 1850 | E18: 2.2 | F18: 0 | G18: 1850 | H18: 0 | I18: 0 | J18: 45895 | K18: 46234 | M18: 0
A19: 2F | B19: 840 | C19: Anna Beshoar | D19: 1850 | E19: 2.2 | F19: 0 | G19: 1850 | H19: 20 | I19: 0.02 | J19: 45895 | K19: 46234 | M19: 0
A20: 2G | B20: 960 | C20: Xinyue Zhang | D20: 1950 | E20: 2.03 | F20: 0 | G20: 3900 | H20: 20 | I20: 0.02 | J20: 45874 | K20: 46234 | M20: 0
A21: 3A | B21: 840 | C21: Dinala Hailati | D21: 1700 | E21: 2.02 | F21: 0 | G21: 1700 | H21: 20 | I21: 0.02 | J21: 45873 | K21: 46234 | M21: 0
A22: 3B | B22: 840 | C22: Zachary Kaminskyj | D22: 800 | E22: 0.95 | F22: 0 | G22: 800 | H22: 10 | I22: 0.01 | J22: 45462 | K22: 46234 | M22: 0
A23: 3C | B23: 540 | C23: John Kim | D23: 1450 | E23: 2.69 | F23: 0 | G23: 0 | H23: 0 | I23: 0 | J23: 45873 | K23: 46234 | M23: 0
A24: 3D | B24: 540 | C24: Evan Blake | D24: 1450 | E24: 2.69 | F24: 0 | G24: 1375 | H24: 20 | I24: 0.04 | J24: 45079 | K24: 46234 | M24: 2495
... A35: 3B-1 | B35: 960 | C35: Trent Wilkinson | D35: 925 | E35: 0.96 | F35: 950 | G35: 0 | H35: 0 | I35: 0 | J35: 45870 | K35: 46234 | M35: 0
A36: Total | C36: Cherry Commons - 1718 N Sydenham | D36: 44160 | E36: 2.07 | F36: 4125 | G36: 45380 | H36: 270 | I36: 0.01 | M36: 2495
D37: =D36*12 -> 529920
A39: Summary Groups | C39: Square | D39: Actual | F39: Security | G39: Other | H39: Misc | J39: # Of | K39: % Unit | L39: % Sqft | M39: Balance
C40: Footage | D40: Rent | F40: Deposit | G40: Deposits | J40: Units | K40: Occupancy | L40: Occupied
A41: Current/Notice/Vacant Tenants | C41: 21300 | D41: 44160 | F41: 4125 | G41: 45380 | H41: 270 | J41: 28 | K41: 96.42 | L41: 96.05 | M41: 2495
A42: Future Tenants/Applicants | C42: 0 | D42: 0 | F42: 0 | G42: 0 | H42: 0 | J42: 0 | K42: 0 | L42: 0 | M42: 0
A43: Occupied Units | C43: 20460 | D43: 0 | F43: 0 | G43: 0 | H43: 0 | J43: 27 | K43: 96.42 | L43: 96.05 | M43: 0
A44: Total Non Rev Units | C44: 0 | D44: 0 | F44: 0 | G44: 0 | H44: 0 | J44: 0 | K44: 0 | L44: 0
A45: Total Vacant Units | C45: 840 | D45: 0 | F45: 0 | G45: 0 | H45: 0 | J45: 1 | K45: 3.57 | L45: 3.94 | M45: 0
A46: Totals: | C46: 21300 | D46: 44160 | F46: 4125 | G46: 45380 | H46: 270 | J46: 28 | K46: 100 | L46: 100 | M46: 2495

Sheet Debt Current
B2: ='Debt Refinance'!B2 -> Address: 1718 North Sydenham Street Philadelphia, PA 19121
B5: Loan Amount | I5: 4000000
B7: Principal | I7: 4200000
B8: Interest per annum | I8: 0.0325
B9: Interest per month | I9: =I8/12 -> 0.0027083333
B10: Mortgage Constant | I10: =I9/(1-(1/(1+I9)^I16)) -> 0.0043520632
B12: Commencement date | I12: 44136
B13: Final maturity date | I13: 19815
B15: Duration (Years) | I15: 30
B16: Duration (Months) | I16: =I15*12 -> 360
B18: Mortgage Insurance Premium
B19: Mortgage Insurance Premium per annum | I19: 0
B20: Mortgage Insurance Premium per month | I20: =I19/12 -> 0
B22: Annual Mortgage Payments 每年房贷还款额 | I22: =E26*12 -> 219343.98
B23: Interest per year Payment | I23: =I7*I8 -> 136500
B25: # Month | C25: Month | D25: Beg Bal | E25: Mortgage Payment | F25: Interest | G25: Amortization | H25: End Bal | I25: Insurance Premium | J25: Mortgage + Insurance Premium | K25: Yearly MIP
B26: 1 | C26: 44136 | D26: =I7 -> 4200000 | E26: =$D$26*$I$10 -> 18278.665 | F26: =D26*$I$9 -> 11375 | G26: =E26-F26 -> 6903.6654 | H26: =D26-G26 -> 4193096.3 | I26: =$I$20*D26 -> 0 | J26: =E26+I26 -> 18278.665 | K26: =SUM(I26:I37) -> 0
B27: =B26+1 -> 2 | C27: 44166 | D27: =H26 -> 4193096.3 | E27: =$D$26*$I$10 -> 18278.665 | F27: =D27*$I$9 -> 11356.303 | G27: =E27-F27 -> 6922.3628 | H27: =D27-G27 -> 4186174 | I27: =$I$20*D27 -> 0 | J27: =E27+I27 -> 18278.665
B28: =B27+1 -> 3 | C28: 44197 | D28: =H27 -> 4186174 | E28: =$D$26*$I$10 -> 18278.665 | F28: =D28*$I$9 -> 11337.555 | G28: =E28-F28 -> 6941.1109 | H28: =D28-G28 -> 4179232.9 | I28: =$I$20*D28 -> 0 | J28: =E28+I28 -> 18278.665
B29: =B28+1 -> 4 | C29: 44228 | D29: =H28 -> 4179232.9 | E29: =$D$26*$I$10 -> 18278.665 | F29: =D29*$I$9 -> 11318.756 | G29: =E29-F29 -> 6959.9097 | H29: =D29-G29 -> 4172273 | I29: =$I$20*D29 -> 0 | J29: =E29+I29 -> 18278.665
B30: =B29+1 -> 5 | C30: 44256 | D30: =H29 -> 4172273 | E30: =$D$26*$I$10 -> 18278.665 | F30: =D30*$I$9 -> 11299.906 | G30: =E30-F30 -> 6978.7595 | H30: =D30-G30 -> 4165294.2 | I30: =$I$20*D30 -> 0 | J30: =E30+I30 -> 18278.665
B31: =B30+1 -> 6 | C31: 44287 | D31: =H30 -> 4165294.2 | E31: =$D$26*$I$10 -> 18278.665 | F31: =D31*$I$9 -> 11281.005 | G31: =E31-F31 -> 6997.6603 | H31: =D31-G31 -> 4158296.5 | I31: =$I$20*D31 -> 0 | J31: =E31+I31 -> 18278.665
B32: =B31+1 -> 7 | C32: 44317 | D32: =H31 -> 4158296.5 | E32: =$D$26*$I$10 -> 18278.665 | F32: =D32*$I$9 -> 11262.053 | G32: =E32-F32 -> 7016.6123 | H32: =D32-G32 -> 4151279.9 | I32: =$I$20*D32 -> 0 | J32: =E32+I32 -> 18278.665
B33: =B32+1 -> 8 | C33: 44348 | D33: =H32 -> 4151279.9 | E33: =$D$26*$I$10 -> 18278.665 | F33: =D33*$I$9 -> 11243.05 | G33: =E33-F33 -> 7035.6156 | H33: =D33-G33 -> 4144244.3 | I33: =$I$20*D33 -> 0 | J33: =E33+I33 -> 18278.665
B34: =B33+1 -> 9 | C34: 44378 | D34: =H33 -> 4144244.3 | E34: =$D$26*$I$10 -> 18278.665 | F34: =D34*$I$9 -> 11223.995 | G34: =E34-F34 -> 7054.6704 | H34: =D34-G34 -> 4137189.6 | I34: =$I$20*D34 -> 0 | J34: =E34+I34 -> 18278.665
B35: =B34+1 -> 10 | C35: 44409 | D35: =H34 -> 4137189.6 | E35: =$D$26*$I$10 -> 18278.665 | F35: =D35*$I$9 -> 11204.889 | G35: =E35-F35 -> 7073.7768 | H35: =D35-G35 -> 4130115.9 | I35: =$I$20*D35 -> 0 | J35: =E35+I35 -> 18278.665
B36: =B35+1 -> 11 | C36: 44440 | D36: =H35 -> 4130115.9 | E36: =$D$26*$I$10 -> 18278.665 | F36: =D36*$I$9 -> 11185.73 | G36: =E36-F36 -> 7092.935 | H36: =D36-G36 -> 4123022.9 | I36: =$I$20*D36 -> 0 | J36: =E36+I36 -> 18278.665
B37: =B36+1 -> 12 | C37: 44470 | D37: =H36 -> 4123022.9 | E37: =$D$26*$I$10 -> 18278.665 | F37: =D37*$I$9 -> 11166.52 | G37: =E37-F37 -> 7112.145 | H37: =D37-G37 -> 4115910.8 | I37: =$I$20*D37 -> 0 | J37: =E37+I37 -> 18278.665
B38: =B37+1 -> 13 | C38: 44501 | D38: =H37 -> 4115910.8 | E38: =$D$26*$I$10 -> 18278.665 | F38: =D38*$I$9 -> 11147.258 | G38: =E38-F38 -> 7131.407 | H38: =D38-G38 -> 4108779.4 | I38: =$I$20*D38 -> 0 | J38: =E38+I38 -> 18278.665 | K38: =SUM(I38:I49) -> 0
B39: =B38+1 -> 14 | C39: 44531 | D39: =H38 -> 4108779.4 | E39: =$D$26*$I$10 -> 18278.665 | F39: =D39*$I$9 -> 11127.944 | G39: =E39-F39 -> 7150.7213 | H39: =D39-G39 -> 4101628.6 | I39: =$I$20*D39 -> 0 | J39: =E39+I39 -> 18278.665
B40: =B39+1 -> 15 | C40: 44562 | D40: =H39 -> 4101628.6 | E40: =$D$26*$I$10 -> 18278.665 | F40: =D40*$I$9 -> 11108.578 | G40: =E40-F40 -> 7170.0878 | H40: =D40-G40 -> 4094458.6 | I40: =$I$20*D40 -> 0 | J40: =E40+I40 -> 18278.665
B41: =B40+1 -> 16 | C41: 44593 | D41: =H40 -> 4094458.6 | E41: =$D$26*$I$10 -> 18278.665 | F41: =D41*$I$9 -> 11089.159 | G41: =E41-F41 -> 7189.5068 | H41: =D41-G41 -> 4087269.1 | I41: =$I$20*D41 -> 0 | J41: =E41+I41 -> 18278.665
B42: =B41+1 -> 17 | C42: 44621 | D42: =H41 -> 4087269.1 | E42: =$D$26*$I$10 -> 18278.665 | F42: =D42*$I$9 -> 11069.687 | G42: =E42-F42 -> 7208.9784 | H42: =D42-G42 -> 4080060.1 | I42: =$I$20*D42 -> 0 | J42: =E42+I42 -> 18278.665
B43: =B42+1 -> 18 | C43: 44652 | D43: =H42 -> 4080060.1 | E43: =$D$26*$I$10 -> 18278.665 | F43: =D43*$I$9 -> 11050.163 | G43: =E43-F43 -> 7228.5027 | H43: =D43-G43 -> 4072831.6 | I43: =$I$20*D43 -> 0 | J43: =E43+I43 -> 18278.665
B44: =B43+1 -> 19 | C44: 44682 | D44: =H43 -> 4072831.6 | E44: =$D$26*$I$10 -> 18278.665 | F44: =D44*$I$9 -> 11030.586 | G44: =E44-F44 -> 7248.0799 | H44: =D44-G44 -> 4065583.5 | I44: =$I$20*D44 -> 0 | J44: =E44+I44 -> 18278.665
B45: =B44+1 -> 20 | C45: 44713 | D45: =H44 -> 4065583.5 | E45: =$D$26*$I$10 -> 18278.665 | F45: =D45*$I$9 -> 11010.955 | G45: =E45-F45 -> 7267.7101 | H45: =D45-G45 -> 4058315.8 | I45: =$I$20*D45 -> 0 | J45: =E45+I45 -> 18278.665
B46: =B45+1 -> 21 | C46: 44743 | D46: =H45 -> 4058315.8 | E46: =$D$26*$I$10 -> 18278.665 | F46: =D46*$I$9 -> 10991.272 | G46: =E46-F46 -> 7287.3935 | H46: =D46-G46 -> 4051028.4 | I46: =$I$20*D46 -> 0 | J46: =E46+I46 -> 18278.665
B47: =B46+1 -> 22 | C47: 44774 | D47: =H46 -> 4051028.4 | E47: =$D$26*$I$10 -> 18278.665 | F47: =D47*$I$9 -> 10971.535 | G47: =E47-F47 -> 7307.1302 | H47: =D47-G47 -> 4043721.3 | I47: =$I$20*D47 -> 0 | J47: =E47+I47 -> 18278.665
B48: =B47+1 -> 23 | C48: 44805 | D48: =H47 -> 4043721.3 | E48: =$D$26*$I$10 -> 18278.665 | F48: =D48*$I$9 -> 10951.745 | G48: =E48-F48 -> 7326.9203 | H48: =D48-G48 -> 4036394.3 | I48: =$I$20*D48 -> 0 | J48: =E48+I48 -> 18278.665
B49: =B48+1 -> 24 | C49: 44835 | D49: =H48 -> 4036394.3 | E49: =$D$26*$I$10 -> 18278.665 | F49: =D49*$I$9 -> 10931.901 | G49: =E49-F49 -> 7346.7641 | H49: =D49-G49 -> 4029047.6 | I49: =$I$20*D49 -> 0 | J49: =E49+I49 -> 18278.665
...

Sheet Debt Refinance
B2: ='Pro-forma'!B3 -> Address: 1718 North Sydenham Street Philadelphia, PA 19121
B5: Loan Amount | I5: ='Pro-forma'!U133 -> 3962686.5
B7: Principal | I7: =I5 -> 3962686.5
B8: Interest per annum | I8: 0.055
B9: Interest per month | I9: =I8/12 -> 0.0045833333
B10: Mortgage Constant | I10: =I9/(1-(1/(1+I9)^I16)) -> 0.00567789
B12: Commencement date | I12: 47058
B13: Final maturity date | I13: 19815
B15: Duration (Years) | I15: 30
B16: Duration (Months) | I16: =I15*12 -> 360
B18: Mortgage Insurance Premium
B19: Mortgage Insurance Premium per annum | I19: 0
B20: Mortgage Insurance Premium per month | I20: =I19/12 -> 0
B22: Annual Mortgage Payments | I22: =E26*12 -> 269996.37 | J22: =I22*15 -> 4049945.6
H23: I/O | I23: =I7*I8 -> 217947.76
B25: # Month | C25: Month | D25: Beg Bal | E25: Mortgage Payment | F25: Interest | G25: Amortization | H25: End Bal | I25: Insurance Premium | J25: Mortgage + Insurance Premium | K25: Yearly MIP
B26: 1 | C26: 44136 | D26: =I7 -> 3962686.5 | E26: =$D$26*$I$10 -> 22499.698 | F26: =D26*$I$9 -> 18162.313 | G26: =E26-F26 -> 4337.3849 | H26: =D26-G26 -> 3958349.1 | I26: =$I$20*D26 -> 0 | J26: =E26+I26 -> 22499.698 | K26: =SUM(I26:I37) -> 0
B27: =B26+1 -> 2 | C27: 44166 | D27: =H26 -> 3958349.1 | E27: =$D$26*$I$10 -> 22499.698 | F27: =D27*$I$9 -> 18142.433 | G27: =E27-F27 -> 4357.2646 | H27: =D27-G27 -> 3953991.8 | I27: =$I$20*D27 -> 0 | J27: =E27+I27 -> 22499.698
B28: =B27+1 -> 3 | C28: 44197 | D28: =H27 -> 3953991.8 | E28: =$D$26*$I$10 -> 22499.698 | F28: =D28*$I$9 -> 18122.462 | G28: =E28-F28 -> 4377.2354 | H28: =D28-G28 -> 3949614.6 | I28: =$I$20*D28 -> 0 | J28: =E28+I28 -> 22499.698
B29: =B28+1 -> 4 | C29: 44228 | D29: =H28 -> 3949614.6 | E29: =$D$26*$I$10 -> 22499.698 | F29: =D29*$I$9 -> 18102.4 | G29: =E29-F29 -> 4397.2977 | H29: =D29-G29 -> 3945217.3 | I29: =$I$20*D29 -> 0 | J29: =E29+I29 -> 22499.698
B30: =B29+1 -> 5 | C30: 44256 | D30: =H29 -> 3945217.3 | E30: =$D$26*$I$10 -> 22499.698 | F30: =D30*$I$9 -> 18082.246 | G30: =E30-F30 -> 4417.452 | H30: =D30-G30 -> 3940799.8 | I30: =$I$20*D30 -> 0 | J30: =E30+I30 -> 22499.698
B31: =B30+1 -> 6 | C31: 44287 | D31: =H30 -> 3940799.8 | E31: =$D$26*$I$10 -> 22499.698 | F31: =D31*$I$9 -> 18061.999 | G31: =E31-F31 -> 4437.6987 | H31: =D31-G31 -> 3936362.1 | I31: =$I$20*D31 -> 0 | J31: =E31+I31 -> 22499.698
B32: =B31+1 -> 7 | C32: 44317 | D32: =H31 -> 3936362.1 | E32: =$D$26*$I$10 -> 22499.698 | F32: =D32*$I$9 -> 18041.66 | G32: =E32-F32 -> 4458.0381 | H32: =D32-G32 -> 3931904.1 | I32: =$I$20*D32 -> 0 | J32: =E32+I32 -> 22499.698
B33: =B32+1 -> 8 | C33: 44348 | D33: =H32 -> 3931904.1 | E33: =$D$26*$I$10 -> 22499.698 | F33: =D33*$I$9 -> 18021.227 | G33: =E33-F33 -> 4478.4708 | H33: =D33-G33 -> 3927425.6 | I33: =$I$20*D33 -> 0 | J33: =E33+I33 -> 22499.698
B34: =B33+1 -> 9 | C34: 44378 | D34: =H33 -> 3927425.6 | E34: =$D$26*$I$10 -> 22499.698 | F34: =D34*$I$9 -> 18000.701 | G34: =E34-F34 -> 4498.9971 | H34: =D34-G34 -> 3922926.6 | I34: =$I$20*D34 -> 0 | J34: =E34+I34 -> 22499.698
B35: =B34+1 -> 10 | C35: 44409 | D35: =H34 -> 3922926.6 | E35: =$D$26*$I$10 -> 22499.698 | F35: =D35*$I$9 -> 17980.08 | G35: =E35-F35 -> 4519.6175 | H35: =D35-G35 -> 3918407 | I35: =$I$20*D35 -> 0 | J35: =E35+I35 -> 22499.698
B36: =B35+1 -> 11 | C36: 44440 | D36: =H35 -> 3918407 | E36: =$D$26*$I$10 -> 22499.698 | F36: =D36*$I$9 -> 17959.365 | G36: =E36-F36 -> 4540.3325 | H36: =D36-G36 -> 3913866.7 | I36: =$I$20*D36 -> 0 | J36: =E36+I36 -> 22499.698
B37: =B36+1 -> 12 | C37: 44470 | D37: =H36 -> 3913866.7 | E37: =$D$26*$I$10 -> 22499.698 | F37: =D37*$I$9 -> 17938.556 | G37: =E37-F37 -> 4561.1423 | H37: =D37-G37 -> 3909305.5 | I37: =$I$20*D37 -> 0 | J37: =E37+I37 -> 22499.698
B38: =B37+1 -> 13 | C38: 44501 | D38: =H37 -> 3909305.5 | E38: =$D$26*$I$10 -> 22499.698 | F38: =D38*$I$9 -> 17917.65 | G38: =E38-F38 -> 4582.0475 | H38: =D38-G38 -> 3904723.5 | I38: =$I$20*D38 -> 0 | J38: =E38+I38 -> 22499.698 | K38: =SUM(I38:I49) -> 0
B39: =B38+1 -> 14 | C39: 44531 | D39: =H38 -> 3904723.5 | E39: =$D$26*$I$10 -> 22499.698 | F39: =D39*$I$9 -> 17896.649 | G39: =E39-F39 -> 4603.0486 | H39: =D39-G39 -> 3900120.4 | I39: =$I$20*D39 -> 0 | J39: =E39+I39 -> 22499.698
B40: =B39+1 -> 15 | C40: 44562 | D40: =H39 -> 3900120.4 | E40: =$D$26*$I$10 -> 22499.698 | F40: =D40*$I$9 -> 17875.552 | G40: =E40-F40 -> 4624.1459 | H40: =D40-G40 -> 3895496.3 | I40: =$I$20*D40 -> 0 | J40: =E40+I40 -> 22499.698
B41: =B40+1 -> 16 | C41: 44593 | D41: =H40 -> 3895496.3 | E41: =$D$26*$I$10 -> 22499.698 | F41: =D41*$I$9 -> 17854.358 | G41: =E41-F41 -> 4645.3399 | H41: =D41-G41 -> 3890851 | I41: =$I$20*D41 -> 0 | J41: =E41+I41 -> 22499.698
B42: =B41+1 -> 17 | C42: 44621 | D42: =H41 -> 3890851 | E42: =$D$26*$I$10 -> 22499.698 | F42: =D42*$I$9 -> 17833.067 | G42: =E42-F42 -> 4666.631 | H42: =D42-G42 -> 3886184.3 | I42: =$I$20*D42 -> 0 | J42: =E42+I42 -> 22499.698
B43: =B42+1 -> 18 | C43: 44652 | D43: =H42 -> 3886184.3 | E43: =$D$26*$I$10 -> 22499.698 | F43: =D43*$I$9 -> 17811.678 | G43: =E43-F43 -> 4688.0198 | H43: =D43-G43 -> 3881496.3 | I43: =$I$20*D43 -> 0 | J43: =E43+I43 -> 22499.698
B44: =B43+1 -> 19 | C44: 44682 | D44: =H43 -> 3881496.3 | E44: =$D$26*$I$10 -> 22499.698 | F44: =D44*$I$9 -> 17790.191 | G44: =E44-F44 -> 4709.5065 | H44: =D44-G44 -> 3876786.8 | I44: =$I$20*D44 -> 0 | J44: =E44+I44 -> 22499.698
B45: =B44+1 -> 20 | C45: 44713 | D45: =H44 -> 3876786.8 | E45: =$D$26*$I$10 -> 22499.698 | F45: =D45*$I$9 -> 17768.606 | G45: =E45-F45 -> 4731.0918 | H45: =D45-G45 -> 3872055.7 | I45: =$I$20*D45 -> 0 | J45: =E45+I45 -> 22499.698
B46: =B45+1 -> 21 | C46: 44743 | D46: =H45 -> 3872055.7 | E46: =$D$26*$I$10 -> 22499.698 | F46: =D46*$I$9 -> 17746.922 | G46: =E46-F46 -> 4752.7759 | H46: =D46-G46 -> 3867302.9 | I46: =$I$20*D46 -> 0 | J46: =E46+I46 -> 22499.698
B47: =B46+1 -> 22 | C47: 44774 | D47: =H46 -> 3867302.9 | E47: =$D$26*$I$10 -> 22499.698 | F47: =D47*$I$9 -> 17725.138 | G47: =E47-F47 -> 4774.5595 | H47: =D47-G47 -> 3862528.4 | I47: =$I$20*D47 -> 0 | J47: =E47+I47 -> 22499.698
B48: =B47+1 -> 23 | C48: 44805 | D48: =H47 -> 3862528.4 | E48: =$D$26*$I$10 -> 22499.698 | F48: =D48*$I$9 -> 17703.255 | G48: =E48-F48 -> 4796.4429 | H48: =D48-G48 -> 3857731.9 | I48: =$I$20*D48 -> 0 | J48: =E48+I48 -> 22499.698
B49: =B48+1 -> 24 | C49: 44835 | D49: =H48 -> 3857731.9 | E49: =$D$26*$I$10 -> 22499.698 | F49: =D49*$I$9 -> 17681.271 | G49: =E49-F49 -> 4818.4266 | H49: =D49-G49 -> 3852913.5 | I49: =$I$20*D49 -> 0 | J49: =E49+I49 -> 22499.698
...
